Exception on /testpost [POST]
Traceback (most recent call last):
  File "C:\Users\pratik\Anaconda3\lib\site-packages\flask\app.py", line 2292, in wsgi_app
    response = self.full_dispatch_request()
  File "C:\Users\pratik\Anaconda3\lib\site-packages\flask\app.py", line 1816, in full_dispatch_request
    return self.finalize_request(rv)
  File "C:\Users\pratik\Anaconda3\lib\site-packages\flask\app.py", line 1831, in finalize_request
    response = self.make_response(rv)
  File "C:\Users\pratik\Anaconda3\lib\site-packages\flask\app.py", line 1957, in make_response
    'The view function did not return a valid response. The'
TypeError: The view function did not return a valid response. The function either returned None or ended without a return statement.
Exception on /testpost [POST]
Traceback (most recent call last):
  File "C:\Users\pratik\Anaconda3\lib\site-packages\flask\app.py", line 2292, in wsgi_app
    response = self.full_dispatch_request()
  File "C:\Users\pratik\Anaconda3\lib\site-packages\flask\app.py", line 1815, in full_dispatch_request
    rv = self.handle_user_exception(e)
  File "C:\Users\pratik\Anaconda3\lib\site-packages\flask_cors\extension.py", line 161, in wrapped_function
    return cors_after_request(app.make_response(f(*args, **kwargs)))
  File "C:\Users\pratik\Anaconda3\lib\site-packages\flask\app.py", line 1718, in handle_user_exception
    reraise(exc_type, exc_value, tb)
  File "C:\Users\pratik\Anaconda3\lib\site-packages\flask\_compat.py", line 35, in reraise
    raise value
  File "C:\Users\pratik\Anaconda3\lib\site-packages\flask\app.py", line 1813, in full_dispatch_request
    rv = self.dispatch_request()
  File "C:\Users\pratik\Anaconda3\lib\site-packages\flask\app.py", line 1799, in dispatch_request
    return self.view_functions[rule.endpoint](**req.view_args)
  File "api_speedo.py", line 32, in test_post
    for filename, file in request.FILES.iteritems():
  File "C:\Users\pratik\Anaconda3\lib\site-packages\werkzeug\local.py", line 347, in __getattr__
    return getattr(self._get_current_object(), name)
AttributeError: 'Request' object has no attribute 'FILES'
Exception on /testpost [POST]
Traceback (most recent call last):
  File "C:\Users\pratik\Anaconda3\lib\site-packages\flask\app.py", line 2292, in wsgi_app
    response = self.full_dispatch_request()
  File "C:\Users\pratik\Anaconda3\lib\site-packages\flask\app.py", line 1815, in full_dispatch_request
    rv = self.handle_user_exception(e)
  File "C:\Users\pratik\Anaconda3\lib\site-packages\flask_cors\extension.py", line 161, in wrapped_function
    return cors_after_request(app.make_response(f(*args, **kwargs)))
  File "C:\Users\pratik\Anaconda3\lib\site-packages\flask\app.py", line 1718, in handle_user_exception
    reraise(exc_type, exc_value, tb)
  File "C:\Users\pratik\Anaconda3\lib\site-packages\flask\_compat.py", line 35, in reraise
    raise value
  File "C:\Users\pratik\Anaconda3\lib\site-packages\flask\app.py", line 1813, in full_dispatch_request
    rv = self.dispatch_request()
  File "C:\Users\pratik\Anaconda3\lib\site-packages\flask\app.py", line 1799, in dispatch_request
    return self.view_functions[rule.endpoint](**req.view_args)
  File "api_speedo.py", line 32, in test_post
    for filename, file in request.FILES.iteritems():
  File "C:\Users\pratik\Anaconda3\lib\site-packages\werkzeug\local.py", line 347, in __getattr__
    return getattr(self._get_current_object(), name)
AttributeError: 'Request' object has no attribute 'FILES'
Exception on /testpost [POST]
Traceback (most recent call last):
  File "C:\Users\pratik\Anaconda3\lib\site-packages\flask\app.py", line 2292, in wsgi_app
    response = self.full_dispatch_request()
  File "C:\Users\pratik\Anaconda3\lib\site-packages\flask\app.py", line 1815, in full_dispatch_request
    rv = self.handle_user_exception(e)
  File "C:\Users\pratik\Anaconda3\lib\site-packages\flask_cors\extension.py", line 161, in wrapped_function
    return cors_after_request(app.make_response(f(*args, **kwargs)))
  File "C:\Users\pratik\Anaconda3\lib\site-packages\flask\app.py", line 1718, in handle_user_exception
    reraise(exc_type, exc_value, tb)
  File "C:\Users\pratik\Anaconda3\lib\site-packages\flask\_compat.py", line 35, in reraise
    raise value
  File "C:\Users\pratik\Anaconda3\lib\site-packages\flask\app.py", line 1813, in full_dispatch_request
    rv = self.dispatch_request()
  File "C:\Users\pratik\Anaconda3\lib\site-packages\flask\app.py", line 1799, in dispatch_request
    return self.view_functions[rule.endpoint](**req.view_args)
  File "api_speedo.py", line 32, in test_post
    for filename, file in request.files.iteritems():
AttributeError: 'ImmutableMultiDict' object has no attribute 'iteritems'
Exception on /testpost [POST]
Traceback (most recent call last):
  File "C:\Users\pratik\Anaconda3\lib\site-packages\flask\app.py", line 2292, in wsgi_app
    response = self.full_dispatch_request()
  File "C:\Users\pratik\Anaconda3\lib\site-packages\flask\app.py", line 1815, in full_dispatch_request
    rv = self.handle_user_exception(e)
  File "C:\Users\pratik\Anaconda3\lib\site-packages\flask_cors\extension.py", line 161, in wrapped_function
    return cors_after_request(app.make_response(f(*args, **kwargs)))
  File "C:\Users\pratik\Anaconda3\lib\site-packages\flask\app.py", line 1718, in handle_user_exception
    reraise(exc_type, exc_value, tb)
  File "C:\Users\pratik\Anaconda3\lib\site-packages\flask\_compat.py", line 35, in reraise
    raise value
  File "C:\Users\pratik\Anaconda3\lib\site-packages\flask\app.py", line 1813, in full_dispatch_request
    rv = self.dispatch_request()
  File "C:\Users\pratik\Anaconda3\lib\site-packages\flask\app.py", line 1799, in dispatch_request
    return self.view_functions[rule.endpoint](**req.view_args)
  File "api_speedo.py", line 32, in test_post
    for filename, file in request.files.iteritems():
AttributeError: 'ImmutableMultiDict' object has no attribute 'iteritems'
Exception on /testpost [POST]
Traceback (most recent call last):
  File "C:\Users\pratik\Anaconda3\lib\site-packages\flask\app.py", line 2292, in wsgi_app
    response = self.full_dispatch_request()
  File "C:\Users\pratik\Anaconda3\lib\site-packages\flask\app.py", line 1815, in full_dispatch_request
    rv = self.handle_user_exception(e)
  File "C:\Users\pratik\Anaconda3\lib\site-packages\flask_cors\extension.py", line 161, in wrapped_function
    return cors_after_request(app.make_response(f(*args, **kwargs)))
  File "C:\Users\pratik\Anaconda3\lib\site-packages\flask\app.py", line 1718, in handle_user_exception
    reraise(exc_type, exc_value, tb)
  File "C:\Users\pratik\Anaconda3\lib\site-packages\flask\_compat.py", line 35, in reraise
    raise value
  File "C:\Users\pratik\Anaconda3\lib\site-packages\flask\app.py", line 1813, in full_dispatch_request
    rv = self.dispatch_request()
  File "C:\Users\pratik\Anaconda3\lib\site-packages\flask\app.py", line 1799, in dispatch_request
    return self.view_functions[rule.endpoint](**req.view_args)
  File "api_speedo.py", line 31, in test_post
    print(request.files.name)
AttributeError: 'ImmutableMultiDict' object has no attribute 'name'
Exception on /testpost [POST]
Traceback (most recent call last):
  File "C:\Users\pratik\Anaconda3\lib\site-packages\flask\app.py", line 2292, in wsgi_app
    response = self.full_dispatch_request()
  File "C:\Users\pratik\Anaconda3\lib\site-packages\flask\app.py", line 1815, in full_dispatch_request
    rv = self.handle_user_exception(e)
  File "C:\Users\pratik\Anaconda3\lib\site-packages\flask_cors\extension.py", line 161, in wrapped_function
    return cors_after_request(app.make_response(f(*args, **kwargs)))
  File "C:\Users\pratik\Anaconda3\lib\site-packages\flask\app.py", line 1718, in handle_user_exception
    reraise(exc_type, exc_value, tb)
  File "C:\Users\pratik\Anaconda3\lib\site-packages\flask\_compat.py", line 35, in reraise
    raise value
  File "C:\Users\pratik\Anaconda3\lib\site-packages\flask\app.py", line 1813, in full_dispatch_request
    rv = self.dispatch_request()
  File "C:\Users\pratik\Anaconda3\lib\site-packages\flask\app.py", line 1799, in dispatch_request
    return self.view_functions[rule.endpoint](**req.view_args)
  File "api_speedo.py", line 31, in test_post
    print(request.files.name)
AttributeError: 'ImmutableMultiDict' object has no attribute 'name'
Exception on /testpost [POST]
Traceback (most recent call last):
  File "C:\Users\pratik\Anaconda3\lib\site-packages\flask\app.py", line 2292, in wsgi_app
    response = self.full_dispatch_request()
  File "C:\Users\pratik\Anaconda3\lib\site-packages\flask\app.py", line 1816, in full_dispatch_request
    return self.finalize_request(rv)
  File "C:\Users\pratik\Anaconda3\lib\site-packages\flask\app.py", line 1831, in finalize_request
    response = self.make_response(rv)
  File "C:\Users\pratik\Anaconda3\lib\site-packages\flask\app.py", line 1957, in make_response
    'The view function did not return a valid response. The'
TypeError: The view function did not return a valid response. The function either returned None or ended without a return statement.
Exception on /testpost [POST]
Traceback (most recent call last):
  File "C:\Users\pratik\Anaconda3\lib\site-packages\flask\app.py", line 2292, in wsgi_app
    response = self.full_dispatch_request()
  File "C:\Users\pratik\Anaconda3\lib\site-packages\flask\app.py", line 1816, in full_dispatch_request
    return self.finalize_request(rv)
  File "C:\Users\pratik\Anaconda3\lib\site-packages\flask\app.py", line 1831, in finalize_request
    response = self.make_response(rv)
  File "C:\Users\pratik\Anaconda3\lib\site-packages\flask\app.py", line 1957, in make_response
    'The view function did not return a valid response. The'
TypeError: The view function did not return a valid response. The function either returned None or ended without a return statement.
Exception on /testpost [POST]
Traceback (most recent call last):
  File "C:\Users\pratik\Anaconda3\lib\site-packages\flask\app.py", line 2292, in wsgi_app
    response = self.full_dispatch_request()
  File "C:\Users\pratik\Anaconda3\lib\site-packages\flask\app.py", line 1815, in full_dispatch_request
    rv = self.handle_user_exception(e)
  File "C:\Users\pratik\Anaconda3\lib\site-packages\flask_cors\extension.py", line 161, in wrapped_function
    return cors_after_request(app.make_response(f(*args, **kwargs)))
  File "C:\Users\pratik\Anaconda3\lib\site-packages\flask\app.py", line 1718, in handle_user_exception
    reraise(exc_type, exc_value, tb)
  File "C:\Users\pratik\Anaconda3\lib\site-packages\flask\_compat.py", line 35, in reraise
    raise value
  File "C:\Users\pratik\Anaconda3\lib\site-packages\flask\app.py", line 1813, in full_dispatch_request
    rv = self.dispatch_request()
  File "C:\Users\pratik\Anaconda3\lib\site-packages\flask\app.py", line 1799, in dispatch_request
    return self.view_functions[rule.endpoint](**req.view_args)
  File "api_speedo.py", line 33, in test_post
    response = requests.get(url)
NameError: name 'requests' is not defined
Exception on /testpost [POST]
Traceback (most recent call last):
  File "C:\Users\pratik\Anaconda3\lib\site-packages\flask\app.py", line 2292, in wsgi_app
    response = self.full_dispatch_request()
  File "C:\Users\pratik\Anaconda3\lib\site-packages\flask\app.py", line 1815, in full_dispatch_request
    rv = self.handle_user_exception(e)
  File "C:\Users\pratik\Anaconda3\lib\site-packages\flask_cors\extension.py", line 161, in wrapped_function
    return cors_after_request(app.make_response(f(*args, **kwargs)))
  File "C:\Users\pratik\Anaconda3\lib\site-packages\flask\app.py", line 1718, in handle_user_exception
    reraise(exc_type, exc_value, tb)
  File "C:\Users\pratik\Anaconda3\lib\site-packages\flask\_compat.py", line 35, in reraise
    raise value
  File "C:\Users\pratik\Anaconda3\lib\site-packages\flask\app.py", line 1813, in full_dispatch_request
    rv = self.dispatch_request()
  File "C:\Users\pratik\Anaconda3\lib\site-packages\flask\app.py", line 1799, in dispatch_request
    return self.view_functions[rule.endpoint](**req.view_args)
  File "api_speedo.py", line 33, in test_post
    response = requests.get(url)
NameError: name 'requests' is not defined
Exception on /testpost [POST]
Traceback (most recent call last):
  File "C:\Users\pratik\Anaconda3\lib\site-packages\flask\app.py", line 2292, in wsgi_app
    response = self.full_dispatch_request()
  File "C:\Users\pratik\Anaconda3\lib\site-packages\flask\app.py", line 1815, in full_dispatch_request
    rv = self.handle_user_exception(e)
  File "C:\Users\pratik\Anaconda3\lib\site-packages\flask_cors\extension.py", line 161, in wrapped_function
    return cors_after_request(app.make_response(f(*args, **kwargs)))
  File "C:\Users\pratik\Anaconda3\lib\site-packages\flask\app.py", line 1718, in handle_user_exception
    reraise(exc_type, exc_value, tb)
  File "C:\Users\pratik\Anaconda3\lib\site-packages\flask\_compat.py", line 35, in reraise
    raise value
  File "C:\Users\pratik\Anaconda3\lib\site-packages\flask\app.py", line 1813, in full_dispatch_request
    rv = self.dispatch_request()
  File "C:\Users\pratik\Anaconda3\lib\site-packages\flask\app.py", line 1799, in dispatch_request
    return self.view_functions[rule.endpoint](**req.view_args)
  File "api_speedo.py", line 34, in test_post
    response = requests.get(url)
  File "C:\Users\pratik\AppData\Roaming\Python\Python36\site-packages\requests\api.py", line 75, in get
    return request('get', url, params=params, **kwargs)
  File "C:\Users\pratik\AppData\Roaming\Python\Python36\site-packages\requests\api.py", line 60, in request
    return session.request(method=method, url=url, **kwargs)
  File "C:\Users\pratik\AppData\Roaming\Python\Python36\site-packages\requests\sessions.py", line 533, in request
    resp = self.send(prep, **send_kwargs)
  File "C:\Users\pratik\AppData\Roaming\Python\Python36\site-packages\requests\sessions.py", line 640, in send
    adapter = self.get_adapter(url=request.url)
  File "C:\Users\pratik\AppData\Roaming\Python\Python36\site-packages\requests\sessions.py", line 731, in get_adapter
    raise InvalidSchema("No connection adapters were found for '%s'" % url)
requests.exceptions.InvalidSchema: No connection adapters were found for 'file:///E:/speedometer/horse.wav'
Exception on /testpost [POST]
Traceback (most recent call last):
  File "C:\Users\pratik\Anaconda3\lib\site-packages\flask\app.py", line 2292, in wsgi_app
    response = self.full_dispatch_request()
  File "C:\Users\pratik\Anaconda3\lib\site-packages\flask\app.py", line 1815, in full_dispatch_request
    rv = self.handle_user_exception(e)
  File "C:\Users\pratik\Anaconda3\lib\site-packages\flask_cors\extension.py", line 161, in wrapped_function
    return cors_after_request(app.make_response(f(*args, **kwargs)))
  File "C:\Users\pratik\Anaconda3\lib\site-packages\flask\app.py", line 1718, in handle_user_exception
    reraise(exc_type, exc_value, tb)
  File "C:\Users\pratik\Anaconda3\lib\site-packages\flask\_compat.py", line 35, in reraise
    raise value
  File "C:\Users\pratik\Anaconda3\lib\site-packages\flask\app.py", line 1813, in full_dispatch_request
    rv = self.dispatch_request()
  File "C:\Users\pratik\Anaconda3\lib\site-packages\flask\app.py", line 1799, in dispatch_request
    return self.view_functions[rule.endpoint](**req.view_args)
  File "api_speedo.py", line 34, in test_post
    response = requests.get(url)
  File "C:\Users\pratik\AppData\Roaming\Python\Python36\site-packages\requests\api.py", line 75, in get
    return request('get', url, params=params, **kwargs)
  File "C:\Users\pratik\AppData\Roaming\Python\Python36\site-packages\requests\api.py", line 60, in request
    return session.request(method=method, url=url, **kwargs)
  File "C:\Users\pratik\AppData\Roaming\Python\Python36\site-packages\requests\sessions.py", line 519, in request
    prep = self.prepare_request(req)
  File "C:\Users\pratik\AppData\Roaming\Python\Python36\site-packages\requests\sessions.py", line 462, in prepare_request
    hooks=merge_hooks(request.hooks, self.hooks),
  File "C:\Users\pratik\AppData\Roaming\Python\Python36\site-packages\requests\models.py", line 313, in prepare
    self.prepare_url(url, params)
  File "C:\Users\pratik\AppData\Roaming\Python\Python36\site-packages\requests\models.py", line 387, in prepare_url
    raise MissingSchema(error)
requests.exceptions.MissingSchema: Invalid URL '': No schema supplied. Perhaps you meant http://?
Exception on /testpost [POST]
Traceback (most recent call last):
  File "C:\Users\pratik\Anaconda3\lib\site-packages\flask\app.py", line 2292, in wsgi_app
    response = self.full_dispatch_request()
  File "C:\Users\pratik\Anaconda3\lib\site-packages\flask\app.py", line 1815, in full_dispatch_request
    rv = self.handle_user_exception(e)
  File "C:\Users\pratik\Anaconda3\lib\site-packages\flask_cors\extension.py", line 161, in wrapped_function
    return cors_after_request(app.make_response(f(*args, **kwargs)))
  File "C:\Users\pratik\Anaconda3\lib\site-packages\flask\app.py", line 1718, in handle_user_exception
    reraise(exc_type, exc_value, tb)
  File "C:\Users\pratik\Anaconda3\lib\site-packages\flask\_compat.py", line 35, in reraise
    raise value
  File "C:\Users\pratik\Anaconda3\lib\site-packages\flask\app.py", line 1813, in full_dispatch_request
    rv = self.dispatch_request()
  File "C:\Users\pratik\Anaconda3\lib\site-packages\flask\app.py", line 1799, in dispatch_request
    return self.view_functions[rule.endpoint](**req.view_args)
  File "api_speedo.py", line 34, in test_post
    response = requests.get(url)
  File "C:\Users\pratik\AppData\Roaming\Python\Python36\site-packages\requests\api.py", line 75, in get
    return request('get', url, params=params, **kwargs)
  File "C:\Users\pratik\AppData\Roaming\Python\Python36\site-packages\requests\api.py", line 60, in request
    return session.request(method=method, url=url, **kwargs)
  File "C:\Users\pratik\AppData\Roaming\Python\Python36\site-packages\requests\sessions.py", line 519, in request
    prep = self.prepare_request(req)
  File "C:\Users\pratik\AppData\Roaming\Python\Python36\site-packages\requests\sessions.py", line 462, in prepare_request
    hooks=merge_hooks(request.hooks, self.hooks),
  File "C:\Users\pratik\AppData\Roaming\Python\Python36\site-packages\requests\models.py", line 313, in prepare
    self.prepare_url(url, params)
  File "C:\Users\pratik\AppData\Roaming\Python\Python36\site-packages\requests\models.py", line 387, in prepare_url
    raise MissingSchema(error)
requests.exceptions.MissingSchema: Invalid URL '': No schema supplied. Perhaps you meant http://?
Exception on /testpost [POST]
Traceback (most recent call last):
  File "C:\Users\pratik\Anaconda3\lib\site-packages\flask\app.py", line 2292, in wsgi_app
    response = self.full_dispatch_request()
  File "C:\Users\pratik\Anaconda3\lib\site-packages\flask\app.py", line 1815, in full_dispatch_request
    rv = self.handle_user_exception(e)
  File "C:\Users\pratik\Anaconda3\lib\site-packages\flask_cors\extension.py", line 161, in wrapped_function
    return cors_after_request(app.make_response(f(*args, **kwargs)))
  File "C:\Users\pratik\Anaconda3\lib\site-packages\flask\app.py", line 1718, in handle_user_exception
    reraise(exc_type, exc_value, tb)
  File "C:\Users\pratik\Anaconda3\lib\site-packages\flask\_compat.py", line 35, in reraise
    raise value
  File "C:\Users\pratik\Anaconda3\lib\site-packages\flask\app.py", line 1813, in full_dispatch_request
    rv = self.dispatch_request()
  File "C:\Users\pratik\Anaconda3\lib\site-packages\flask\app.py", line 1799, in dispatch_request
    return self.view_functions[rule.endpoint](**req.view_args)
  File "api_speedo.py", line 34, in test_post
    response = requests.get(url)
  File "C:\Users\pratik\AppData\Roaming\Python\Python36\site-packages\requests\api.py", line 75, in get
    return request('get', url, params=params, **kwargs)
  File "C:\Users\pratik\AppData\Roaming\Python\Python36\site-packages\requests\api.py", line 60, in request
    return session.request(method=method, url=url, **kwargs)
  File "C:\Users\pratik\AppData\Roaming\Python\Python36\site-packages\requests\sessions.py", line 519, in request
    prep = self.prepare_request(req)
  File "C:\Users\pratik\AppData\Roaming\Python\Python36\site-packages\requests\sessions.py", line 462, in prepare_request
    hooks=merge_hooks(request.hooks, self.hooks),
  File "C:\Users\pratik\AppData\Roaming\Python\Python36\site-packages\requests\models.py", line 313, in prepare
    self.prepare_url(url, params)
  File "C:\Users\pratik\AppData\Roaming\Python\Python36\site-packages\requests\models.py", line 387, in prepare_url
    raise MissingSchema(error)
requests.exceptions.MissingSchema: Invalid URL '': No schema supplied. Perhaps you meant http://?
Exception on /testpost [POST]
Traceback (most recent call last):
  File "C:\Users\pratik\Anaconda3\lib\site-packages\flask\app.py", line 2292, in wsgi_app
    response = self.full_dispatch_request()
  File "C:\Users\pratik\Anaconda3\lib\site-packages\flask\app.py", line 1815, in full_dispatch_request
    rv = self.handle_user_exception(e)
  File "C:\Users\pratik\Anaconda3\lib\site-packages\flask_cors\extension.py", line 161, in wrapped_function
    return cors_after_request(app.make_response(f(*args, **kwargs)))
  File "C:\Users\pratik\Anaconda3\lib\site-packages\flask\app.py", line 1718, in handle_user_exception
    reraise(exc_type, exc_value, tb)
  File "C:\Users\pratik\Anaconda3\lib\site-packages\flask\_compat.py", line 35, in reraise
    raise value
  File "C:\Users\pratik\Anaconda3\lib\site-packages\flask\app.py", line 1813, in full_dispatch_request
    rv = self.dispatch_request()
  File "C:\Users\pratik\Anaconda3\lib\site-packages\flask\app.py", line 1799, in dispatch_request
    return self.view_functions[rule.endpoint](**req.view_args)
  File "api_speedo.py", line 34, in test_post
    response = requests.get(url)
  File "C:\Users\pratik\AppData\Roaming\Python\Python36\site-packages\requests\api.py", line 75, in get
    return request('get', url, params=params, **kwargs)
  File "C:\Users\pratik\AppData\Roaming\Python\Python36\site-packages\requests\api.py", line 60, in request
    return session.request(method=method, url=url, **kwargs)
  File "C:\Users\pratik\AppData\Roaming\Python\Python36\site-packages\requests\sessions.py", line 533, in request
    resp = self.send(prep, **send_kwargs)
  File "C:\Users\pratik\AppData\Roaming\Python\Python36\site-packages\requests\sessions.py", line 640, in send
    adapter = self.get_adapter(url=request.url)
  File "C:\Users\pratik\AppData\Roaming\Python\Python36\site-packages\requests\sessions.py", line 731, in get_adapter
    raise InvalidSchema("No connection adapters were found for '%s'" % url)
requests.exceptions.InvalidSchema: No connection adapters were found for 'file:///E:/speedometer/horse.wav'
Exception on /testpost [POST]
Traceback (most recent call last):
  File "C:\Users\pratik\Anaconda3\lib\site-packages\flask\app.py", line 2292, in wsgi_app
    response = self.full_dispatch_request()
  File "C:\Users\pratik\Anaconda3\lib\site-packages\flask\app.py", line 1815, in full_dispatch_request
    rv = self.handle_user_exception(e)
  File "C:\Users\pratik\Anaconda3\lib\site-packages\flask_cors\extension.py", line 161, in wrapped_function
    return cors_after_request(app.make_response(f(*args, **kwargs)))
  File "C:\Users\pratik\Anaconda3\lib\site-packages\flask\app.py", line 1718, in handle_user_exception
    reraise(exc_type, exc_value, tb)
  File "C:\Users\pratik\Anaconda3\lib\site-packages\flask\_compat.py", line 35, in reraise
    raise value
  File "C:\Users\pratik\Anaconda3\lib\site-packages\flask\app.py", line 1813, in full_dispatch_request
    rv = self.dispatch_request()
  File "C:\Users\pratik\Anaconda3\lib\site-packages\flask\app.py", line 1799, in dispatch_request
    return self.view_functions[rule.endpoint](**req.view_args)
  File "api_speedo.py", line 34, in test_post
    response = requests.get(url)
  File "C:\Users\pratik\AppData\Roaming\Python\Python36\site-packages\requests\api.py", line 75, in get
    return request('get', url, params=params, **kwargs)
  File "C:\Users\pratik\AppData\Roaming\Python\Python36\site-packages\requests\api.py", line 60, in request
    return session.request(method=method, url=url, **kwargs)
  File "C:\Users\pratik\AppData\Roaming\Python\Python36\site-packages\requests\sessions.py", line 533, in request
    resp = self.send(prep, **send_kwargs)
  File "C:\Users\pratik\AppData\Roaming\Python\Python36\site-packages\requests\sessions.py", line 640, in send
    adapter = self.get_adapter(url=request.url)
  File "C:\Users\pratik\AppData\Roaming\Python\Python36\site-packages\requests\sessions.py", line 731, in get_adapter
    raise InvalidSchema("No connection adapters were found for '%s'" % url)
requests.exceptions.InvalidSchema: No connection adapters were found for 'file:///E:/speedometer/horse.wav'
Exception on /testpost [POST]
Traceback (most recent call last):
  File "C:\Users\pratik\Anaconda3\lib\site-packages\flask\app.py", line 2292, in wsgi_app
    response = self.full_dispatch_request()
  File "C:\Users\pratik\Anaconda3\lib\site-packages\flask\app.py", line 1815, in full_dispatch_request
    rv = self.handle_user_exception(e)
  File "C:\Users\pratik\Anaconda3\lib\site-packages\flask_cors\extension.py", line 161, in wrapped_function
    return cors_after_request(app.make_response(f(*args, **kwargs)))
  File "C:\Users\pratik\Anaconda3\lib\site-packages\flask\app.py", line 1718, in handle_user_exception
    reraise(exc_type, exc_value, tb)
  File "C:\Users\pratik\Anaconda3\lib\site-packages\flask\_compat.py", line 35, in reraise
    raise value
  File "C:\Users\pratik\Anaconda3\lib\site-packages\flask\app.py", line 1813, in full_dispatch_request
    rv = self.dispatch_request()
  File "C:\Users\pratik\Anaconda3\lib\site-packages\flask\app.py", line 1799, in dispatch_request
    return self.view_functions[rule.endpoint](**req.view_args)
  File "api_speedo.py", line 34, in test_post
    response = requests.get(url)
  File "C:\Users\pratik\AppData\Roaming\Python\Python36\site-packages\requests\api.py", line 75, in get
    return request('get', url, params=params, **kwargs)
  File "C:\Users\pratik\AppData\Roaming\Python\Python36\site-packages\requests\api.py", line 60, in request
    return session.request(method=method, url=url, **kwargs)
  File "C:\Users\pratik\AppData\Roaming\Python\Python36\site-packages\requests\sessions.py", line 519, in request
    prep = self.prepare_request(req)
  File "C:\Users\pratik\AppData\Roaming\Python\Python36\site-packages\requests\sessions.py", line 462, in prepare_request
    hooks=merge_hooks(request.hooks, self.hooks),
  File "C:\Users\pratik\AppData\Roaming\Python\Python36\site-packages\requests\models.py", line 313, in prepare
    self.prepare_url(url, params)
  File "C:\Users\pratik\AppData\Roaming\Python\Python36\site-packages\requests\models.py", line 387, in prepare_url
    raise MissingSchema(error)
requests.exceptions.MissingSchema: Invalid URL '': No schema supplied. Perhaps you meant http://?
Exception on /testpost [POST]
Traceback (most recent call last):
  File "C:\Users\pratik\Anaconda3\lib\site-packages\flask\app.py", line 2292, in wsgi_app
    response = self.full_dispatch_request()
  File "C:\Users\pratik\Anaconda3\lib\site-packages\flask\app.py", line 1815, in full_dispatch_request
    rv = self.handle_user_exception(e)
  File "C:\Users\pratik\Anaconda3\lib\site-packages\flask_cors\extension.py", line 161, in wrapped_function
    return cors_after_request(app.make_response(f(*args, **kwargs)))
  File "C:\Users\pratik\Anaconda3\lib\site-packages\flask\app.py", line 1718, in handle_user_exception
    reraise(exc_type, exc_value, tb)
  File "C:\Users\pratik\Anaconda3\lib\site-packages\flask\_compat.py", line 35, in reraise
    raise value
  File "C:\Users\pratik\Anaconda3\lib\site-packages\flask\app.py", line 1813, in full_dispatch_request
    rv = self.dispatch_request()
  File "C:\Users\pratik\Anaconda3\lib\site-packages\flask\app.py", line 1799, in dispatch_request
    return self.view_functions[rule.endpoint](**req.view_args)
  File "api_speedo.py", line 34, in test_post
    response = requests.get(url)
  File "C:\Users\pratik\AppData\Roaming\Python\Python36\site-packages\requests\api.py", line 75, in get
    return request('get', url, params=params, **kwargs)
  File "C:\Users\pratik\AppData\Roaming\Python\Python36\site-packages\requests\api.py", line 60, in request
    return session.request(method=method, url=url, **kwargs)
  File "C:\Users\pratik\AppData\Roaming\Python\Python36\site-packages\requests\sessions.py", line 533, in request
    resp = self.send(prep, **send_kwargs)
  File "C:\Users\pratik\AppData\Roaming\Python\Python36\site-packages\requests\sessions.py", line 640, in send
    adapter = self.get_adapter(url=request.url)
  File "C:\Users\pratik\AppData\Roaming\Python\Python36\site-packages\requests\sessions.py", line 731, in get_adapter
    raise InvalidSchema("No connection adapters were found for '%s'" % url)
requests.exceptions.InvalidSchema: No connection adapters were found for 'file:///E:/speedometer/horse.wav'
Exception on /testpost [POST]
Traceback (most recent call last):
  File "C:\Users\pratik\Anaconda3\lib\site-packages\flask\app.py", line 2292, in wsgi_app
    response = self.full_dispatch_request()
  File "C:\Users\pratik\Anaconda3\lib\site-packages\flask\app.py", line 1815, in full_dispatch_request
    rv = self.handle_user_exception(e)
  File "C:\Users\pratik\Anaconda3\lib\site-packages\flask_cors\extension.py", line 161, in wrapped_function
    return cors_after_request(app.make_response(f(*args, **kwargs)))
  File "C:\Users\pratik\Anaconda3\lib\site-packages\flask\app.py", line 1718, in handle_user_exception
    reraise(exc_type, exc_value, tb)
  File "C:\Users\pratik\Anaconda3\lib\site-packages\flask\_compat.py", line 35, in reraise
    raise value
  File "C:\Users\pratik\Anaconda3\lib\site-packages\flask\app.py", line 1813, in full_dispatch_request
    rv = self.dispatch_request()
  File "C:\Users\pratik\Anaconda3\lib\site-packages\flask\app.py", line 1799, in dispatch_request
    return self.view_functions[rule.endpoint](**req.view_args)
  File "api_speedo.py", line 34, in test_post
    response = requests.get(url)
  File "C:\Users\pratik\AppData\Roaming\Python\Python36\site-packages\requests\api.py", line 75, in get
    return request('get', url, params=params, **kwargs)
  File "C:\Users\pratik\AppData\Roaming\Python\Python36\site-packages\requests\api.py", line 60, in request
    return session.request(method=method, url=url, **kwargs)
  File "C:\Users\pratik\AppData\Roaming\Python\Python36\site-packages\requests\sessions.py", line 519, in request
    prep = self.prepare_request(req)
  File "C:\Users\pratik\AppData\Roaming\Python\Python36\site-packages\requests\sessions.py", line 462, in prepare_request
    hooks=merge_hooks(request.hooks, self.hooks),
  File "C:\Users\pratik\AppData\Roaming\Python\Python36\site-packages\requests\models.py", line 313, in prepare
    self.prepare_url(url, params)
  File "C:\Users\pratik\AppData\Roaming\Python\Python36\site-packages\requests\models.py", line 387, in prepare_url
    raise MissingSchema(error)
requests.exceptions.MissingSchema: Invalid URL '': No schema supplied. Perhaps you meant http://?
Exception on /testpost [POST]
Traceback (most recent call last):
  File "C:\Users\pratik\Anaconda3\lib\site-packages\flask\app.py", line 2292, in wsgi_app
    response = self.full_dispatch_request()
  File "C:\Users\pratik\Anaconda3\lib\site-packages\flask\app.py", line 1815, in full_dispatch_request
    rv = self.handle_user_exception(e)
  File "C:\Users\pratik\Anaconda3\lib\site-packages\flask_cors\extension.py", line 161, in wrapped_function
    return cors_after_request(app.make_response(f(*args, **kwargs)))
  File "C:\Users\pratik\Anaconda3\lib\site-packages\flask\app.py", line 1718, in handle_user_exception
    reraise(exc_type, exc_value, tb)
  File "C:\Users\pratik\Anaconda3\lib\site-packages\flask\_compat.py", line 35, in reraise
    raise value
  File "C:\Users\pratik\Anaconda3\lib\site-packages\flask\app.py", line 1813, in full_dispatch_request
    rv = self.dispatch_request()
  File "C:\Users\pratik\Anaconda3\lib\site-packages\flask\app.py", line 1799, in dispatch_request
    return self.view_functions[rule.endpoint](**req.view_args)
  File "api_speedo.py", line 36, in test_post
    with open('E:\speedometer', 'wb') as f:
PermissionError: [Errno 13] Permission denied: 'E:\\speedometer'
Exception on /testpost [POST]
Traceback (most recent call last):
  File "C:\Users\pratik\Anaconda3\lib\site-packages\flask\app.py", line 2292, in wsgi_app
    response = self.full_dispatch_request()
  File "C:\Users\pratik\Anaconda3\lib\site-packages\flask\app.py", line 1815, in full_dispatch_request
    rv = self.handle_user_exception(e)
  File "C:\Users\pratik\Anaconda3\lib\site-packages\flask_cors\extension.py", line 161, in wrapped_function
    return cors_after_request(app.make_response(f(*args, **kwargs)))
  File "C:\Users\pratik\Anaconda3\lib\site-packages\flask\app.py", line 1718, in handle_user_exception
    reraise(exc_type, exc_value, tb)
  File "C:\Users\pratik\Anaconda3\lib\site-packages\flask\_compat.py", line 35, in reraise
    raise value
  File "C:\Users\pratik\Anaconda3\lib\site-packages\flask\app.py", line 1813, in full_dispatch_request
    rv = self.dispatch_request()
  File "C:\Users\pratik\Anaconda3\lib\site-packages\flask\app.py", line 1799, in dispatch_request
    return self.view_functions[rule.endpoint](**req.view_args)
  File "api_speedo.py", line 34, in test_post
    response = requests.get(url)
  File "C:\Users\pratik\AppData\Roaming\Python\Python36\site-packages\requests\api.py", line 75, in get
    return request('get', url, params=params, **kwargs)
  File "C:\Users\pratik\AppData\Roaming\Python\Python36\site-packages\requests\api.py", line 60, in request
    return session.request(method=method, url=url, **kwargs)
  File "C:\Users\pratik\AppData\Roaming\Python\Python36\site-packages\requests\sessions.py", line 519, in request
    prep = self.prepare_request(req)
  File "C:\Users\pratik\AppData\Roaming\Python\Python36\site-packages\requests\sessions.py", line 462, in prepare_request
    hooks=merge_hooks(request.hooks, self.hooks),
  File "C:\Users\pratik\AppData\Roaming\Python\Python36\site-packages\requests\models.py", line 313, in prepare
    self.prepare_url(url, params)
  File "C:\Users\pratik\AppData\Roaming\Python\Python36\site-packages\requests\models.py", line 387, in prepare_url
    raise MissingSchema(error)
requests.exceptions.MissingSchema: Invalid URL '': No schema supplied. Perhaps you meant http://?
Exception on /testpost [POST]
Traceback (most recent call last):
  File "C:\Users\pratik\Anaconda3\lib\site-packages\flask\app.py", line 2292, in wsgi_app
    response = self.full_dispatch_request()
  File "C:\Users\pratik\Anaconda3\lib\site-packages\flask\app.py", line 1816, in full_dispatch_request
    return self.finalize_request(rv)
  File "C:\Users\pratik\Anaconda3\lib\site-packages\flask\app.py", line 1831, in finalize_request
    response = self.make_response(rv)
  File "C:\Users\pratik\Anaconda3\lib\site-packages\flask\app.py", line 1957, in make_response
    'The view function did not return a valid response. The'
TypeError: The view function did not return a valid response. The function either returned None or ended without a return statement.
Exception on /testpost [POST]
Traceback (most recent call last):
  File "C:\Users\pratik\Anaconda3\lib\site-packages\flask\app.py", line 2292, in wsgi_app
    response = self.full_dispatch_request()
  File "C:\Users\pratik\Anaconda3\lib\site-packages\flask\app.py", line 1816, in full_dispatch_request
    return self.finalize_request(rv)
  File "C:\Users\pratik\Anaconda3\lib\site-packages\flask\app.py", line 1831, in finalize_request
    response = self.make_response(rv)
  File "C:\Users\pratik\Anaconda3\lib\site-packages\flask\app.py", line 1957, in make_response
    'The view function did not return a valid response. The'
TypeError: The view function did not return a valid response. The function either returned None or ended without a return statement.
Exception on /testpost [POST]
Traceback (most recent call last):
  File "C:\Users\pratik\Anaconda3\lib\site-packages\flask\app.py", line 2292, in wsgi_app
    response = self.full_dispatch_request()
  File "C:\Users\pratik\Anaconda3\lib\site-packages\flask\app.py", line 1816, in full_dispatch_request
    return self.finalize_request(rv)
  File "C:\Users\pratik\Anaconda3\lib\site-packages\flask\app.py", line 1831, in finalize_request
    response = self.make_response(rv)
  File "C:\Users\pratik\Anaconda3\lib\site-packages\flask\app.py", line 1957, in make_response
    'The view function did not return a valid response. The'
TypeError: The view function did not return a valid response. The function either returned None or ended without a return statement.
Exception on /testpost [POST]
Traceback (most recent call last):
  File "C:\Users\pratik\Anaconda3\lib\site-packages\flask\app.py", line 2292, in wsgi_app
    response = self.full_dispatch_request()
  File "C:\Users\pratik\Anaconda3\lib\site-packages\flask\app.py", line 1816, in full_dispatch_request
    return self.finalize_request(rv)
  File "C:\Users\pratik\Anaconda3\lib\site-packages\flask\app.py", line 1831, in finalize_request
    response = self.make_response(rv)
  File "C:\Users\pratik\Anaconda3\lib\site-packages\flask\app.py", line 1957, in make_response
    'The view function did not return a valid response. The'
TypeError: The view function did not return a valid response. The function either returned None or ended without a return statement.
Exception on /testpost [POST]
Traceback (most recent call last):
  File "C:\Users\pratik\Anaconda3\lib\site-packages\flask\app.py", line 2292, in wsgi_app
    response = self.full_dispatch_request()
  File "C:\Users\pratik\Anaconda3\lib\site-packages\flask\app.py", line 1816, in full_dispatch_request
    return self.finalize_request(rv)
  File "C:\Users\pratik\Anaconda3\lib\site-packages\flask\app.py", line 1831, in finalize_request
    response = self.make_response(rv)
  File "C:\Users\pratik\Anaconda3\lib\site-packages\flask\app.py", line 1957, in make_response
    'The view function did not return a valid response. The'
TypeError: The view function did not return a valid response. The function either returned None or ended without a return statement.
Exception on /testpost [POST]
Traceback (most recent call last):
  File "C:\Users\pratik\Anaconda3\lib\site-packages\urllib3\connection.py", line 141, in _new_conn
    (self.host, self.port), self.timeout, **extra_kw)
  File "C:\Users\pratik\Anaconda3\lib\site-packages\urllib3\util\connection.py", line 83, in create_connection
    raise err
  File "C:\Users\pratik\Anaconda3\lib\site-packages\urllib3\util\connection.py", line 73, in create_connection
    sock.connect(sa)
TimeoutError: [WinError 10060] A connection attempt failed because the connected party did not properly respond after a period of time, or established connection failed because connected host has failed to respond

During handling of the above exception, another exception occurred:

Traceback (most recent call last):
  File "C:\Users\pratik\Anaconda3\lib\site-packages\urllib3\connectionpool.py", line 601, in urlopen
    chunked=chunked)
  File "C:\Users\pratik\Anaconda3\lib\site-packages\urllib3\connectionpool.py", line 357, in _make_request
    conn.request(method, url, **httplib_request_kw)
  File "C:\Users\pratik\Anaconda3\lib\http\client.py", line 1239, in request
    self._send_request(method, url, body, headers, encode_chunked)
  File "C:\Users\pratik\Anaconda3\lib\http\client.py", line 1285, in _send_request
    self.endheaders(body, encode_chunked=encode_chunked)
  File "C:\Users\pratik\Anaconda3\lib\http\client.py", line 1234, in endheaders
    self._send_output(message_body, encode_chunked=encode_chunked)
  File "C:\Users\pratik\Anaconda3\lib\http\client.py", line 1026, in _send_output
    self.send(msg)
  File "C:\Users\pratik\Anaconda3\lib\http\client.py", line 964, in send
    self.connect()
  File "C:\Users\pratik\Anaconda3\lib\site-packages\urllib3\connection.py", line 166, in connect
    conn = self._new_conn()
  File "C:\Users\pratik\Anaconda3\lib\site-packages\urllib3\connection.py", line 150, in _new_conn
    self, "Failed to establish a new connection: %s" % e)
urllib3.exceptions.NewConnectionError: <urllib3.connection.HTTPConnection object at 0x000001DD8B4A0668>: Failed to establish a new connection: [WinError 10060] A connection attempt failed because the connected party did not properly respond after a period of time, or established connection failed because connected host has failed to respond

During handling of the above exception, another exception occurred:

Traceback (most recent call last):
  File "C:\Users\pratik\AppData\Roaming\Python\Python36\site-packages\requests\adapters.py", line 449, in send
    timeout=timeout
  File "C:\Users\pratik\Anaconda3\lib\site-packages\urllib3\connectionpool.py", line 639, in urlopen
    _stacktrace=sys.exc_info()[2])
  File "C:\Users\pratik\Anaconda3\lib\site-packages\urllib3\util\retry.py", line 388, in increment
    raise MaxRetryError(_pool, url, error or ResponseError(cause))
urllib3.exceptions.MaxRetryError: HTTPConnectionPool(host='172.16.2.96', port=8080): Max retries exceeded with url: /horse.wav (Caused by NewConnectionError('<urllib3.connection.HTTPConnection object at 0x000001DD8B4A0668>: Failed to establish a new connection: [WinError 10060] A connection attempt failed because the connected party did not properly respond after a period of time, or established connection failed because connected host has failed to respond',))

During handling of the above exception, another exception occurred:

Traceback (most recent call last):
  File "C:\Users\pratik\Anaconda3\lib\site-packages\flask\app.py", line 2292, in wsgi_app
    response = self.full_dispatch_request()
  File "C:\Users\pratik\Anaconda3\lib\site-packages\flask\app.py", line 1815, in full_dispatch_request
    rv = self.handle_user_exception(e)
  File "C:\Users\pratik\Anaconda3\lib\site-packages\flask_cors\extension.py", line 161, in wrapped_function
    return cors_after_request(app.make_response(f(*args, **kwargs)))
  File "C:\Users\pratik\Anaconda3\lib\site-packages\flask\app.py", line 1718, in handle_user_exception
    reraise(exc_type, exc_value, tb)
  File "C:\Users\pratik\Anaconda3\lib\site-packages\flask\_compat.py", line 35, in reraise
    raise value
  File "C:\Users\pratik\Anaconda3\lib\site-packages\flask\app.py", line 1813, in full_dispatch_request
    rv = self.dispatch_request()
  File "C:\Users\pratik\Anaconda3\lib\site-packages\flask\app.py", line 1799, in dispatch_request
    return self.view_functions[rule.endpoint](**req.view_args)
  File "api_speedo.py", line 35, in test_post
    response = requests.get(url)
  File "C:\Users\pratik\AppData\Roaming\Python\Python36\site-packages\requests\api.py", line 75, in get
    return request('get', url, params=params, **kwargs)
  File "C:\Users\pratik\AppData\Roaming\Python\Python36\site-packages\requests\api.py", line 60, in request
    return session.request(method=method, url=url, **kwargs)
  File "C:\Users\pratik\AppData\Roaming\Python\Python36\site-packages\requests\sessions.py", line 533, in request
    resp = self.send(prep, **send_kwargs)
  File "C:\Users\pratik\AppData\Roaming\Python\Python36\site-packages\requests\sessions.py", line 646, in send
    r = adapter.send(request, **kwargs)
  File "C:\Users\pratik\AppData\Roaming\Python\Python36\site-packages\requests\adapters.py", line 516, in send
    raise ConnectionError(e, request=request)
requests.exceptions.ConnectionError: HTTPConnectionPool(host='172.16.2.96', port=8080): Max retries exceeded with url: /horse.wav (Caused by NewConnectionError('<urllib3.connection.HTTPConnection object at 0x000001DD8B4A0668>: Failed to establish a new connection: [WinError 10060] A connection attempt failed because the connected party did not properly respond after a period of time, or established connection failed because connected host has failed to respond',))
Exception on /testpost [POST]
Traceback (most recent call last):
  File "C:\Users\pratik\Anaconda3\lib\site-packages\flask\app.py", line 2292, in wsgi_app
    response = self.full_dispatch_request()
  File "C:\Users\pratik\Anaconda3\lib\site-packages\flask\app.py", line 1816, in full_dispatch_request
    return self.finalize_request(rv)
  File "C:\Users\pratik\Anaconda3\lib\site-packages\flask\app.py", line 1831, in finalize_request
    response = self.make_response(rv)
  File "C:\Users\pratik\Anaconda3\lib\site-packages\flask\app.py", line 1957, in make_response
    'The view function did not return a valid response. The'
TypeError: The view function did not return a valid response. The function either returned None or ended without a return statement.
Exception on /testpost [POST]
Traceback (most recent call last):
  File "C:\Users\pratik\Anaconda3\lib\site-packages\flask\app.py", line 2292, in wsgi_app
    response = self.full_dispatch_request()
  File "C:\Users\pratik\Anaconda3\lib\site-packages\flask\app.py", line 1815, in full_dispatch_request
    rv = self.handle_user_exception(e)
  File "C:\Users\pratik\Anaconda3\lib\site-packages\flask_cors\extension.py", line 161, in wrapped_function
    return cors_after_request(app.make_response(f(*args, **kwargs)))
  File "C:\Users\pratik\Anaconda3\lib\site-packages\flask\app.py", line 1718, in handle_user_exception
    reraise(exc_type, exc_value, tb)
  File "C:\Users\pratik\Anaconda3\lib\site-packages\flask\_compat.py", line 35, in reraise
    raise value
  File "C:\Users\pratik\Anaconda3\lib\site-packages\flask\app.py", line 1813, in full_dispatch_request
    rv = self.dispatch_request()
  File "C:\Users\pratik\Anaconda3\lib\site-packages\flask\app.py", line 1799, in dispatch_request
    return self.view_functions[rule.endpoint](**req.view_args)
  File "api_speedo.py", line 38, in test_post
    return send_file('nodmg.jpg', mimetype='image/jpg')
NameError: name 'send_file' is not defined
Exception on /testpost [POST]
Traceback (most recent call last):
  File "C:\Users\pratik\Anaconda3\lib\site-packages\flask\app.py", line 2292, in wsgi_app
    response = self.full_dispatch_request()
  File "C:\Users\pratik\Anaconda3\lib\site-packages\flask\app.py", line 1815, in full_dispatch_request
    rv = self.handle_user_exception(e)
  File "C:\Users\pratik\Anaconda3\lib\site-packages\flask_cors\extension.py", line 161, in wrapped_function
    return cors_after_request(app.make_response(f(*args, **kwargs)))
  File "C:\Users\pratik\Anaconda3\lib\site-packages\flask\app.py", line 1718, in handle_user_exception
    reraise(exc_type, exc_value, tb)
  File "C:\Users\pratik\Anaconda3\lib\site-packages\flask\_compat.py", line 35, in reraise
    raise value
  File "C:\Users\pratik\Anaconda3\lib\site-packages\flask\app.py", line 1813, in full_dispatch_request
    rv = self.dispatch_request()
  File "C:\Users\pratik\Anaconda3\lib\site-packages\flask\app.py", line 1799, in dispatch_request
    return self.view_functions[rule.endpoint](**req.view_args)
  File "api_speedo.py", line 38, in test_post
    return jsonify(send_file('nodmg.jpg', mimetype='image/jpg'))
  File "C:\Users\pratik\Anaconda3\lib\site-packages\flask\json\__init__.py", line 321, in jsonify
    dumps(data, indent=indent, separators=separators) + '\n',
  File "C:\Users\pratik\Anaconda3\lib\site-packages\flask\json\__init__.py", line 179, in dumps
    rv = _json.dumps(obj, **kwargs)
  File "C:\Users\pratik\Anaconda3\lib\site-packages\simplejson\__init__.py", line 399, in dumps
    **kw).encode(obj)
  File "C:\Users\pratik\Anaconda3\lib\site-packages\simplejson\encoder.py", line 296, in encode
    chunks = self.iterencode(o, _one_shot=True)
  File "C:\Users\pratik\Anaconda3\lib\site-packages\simplejson\encoder.py", line 378, in iterencode
    return _iterencode(o, 0)
  File "C:\Users\pratik\Anaconda3\lib\site-packages\flask\json\__init__.py", line 81, in default
    return _json.JSONEncoder.default(self, o)
  File "C:\Users\pratik\Anaconda3\lib\site-packages\simplejson\encoder.py", line 273, in default
    o.__class__.__name__)
TypeError: Object of type Response is not JSON serializable
Exception on /testpost [POST]
Traceback (most recent call last):
  File "C:\Users\pratik\Anaconda3\lib\site-packages\flask\app.py", line 2292, in wsgi_app
    response = self.full_dispatch_request()
  File "C:\Users\pratik\Anaconda3\lib\site-packages\flask\app.py", line 1815, in full_dispatch_request
    rv = self.handle_user_exception(e)
  File "C:\Users\pratik\Anaconda3\lib\site-packages\flask_cors\extension.py", line 161, in wrapped_function
    return cors_after_request(app.make_response(f(*args, **kwargs)))
  File "C:\Users\pratik\Anaconda3\lib\site-packages\flask\app.py", line 1718, in handle_user_exception
    reraise(exc_type, exc_value, tb)
  File "C:\Users\pratik\Anaconda3\lib\site-packages\flask\_compat.py", line 35, in reraise
    raise value
  File "C:\Users\pratik\Anaconda3\lib\site-packages\flask\app.py", line 1813, in full_dispatch_request
    rv = self.dispatch_request()
  File "C:\Users\pratik\Anaconda3\lib\site-packages\flask\app.py", line 1799, in dispatch_request
    return self.view_functions[rule.endpoint](**req.view_args)
  File "api_speedo.py", line 38, in test_post
    return json.dumps(send_file('nodmg.jpg', mimetype='image/jpg'))
  File "C:\Users\pratik\Anaconda3\lib\json\__init__.py", line 231, in dumps
    return _default_encoder.encode(obj)
  File "C:\Users\pratik\Anaconda3\lib\json\encoder.py", line 199, in encode
    chunks = self.iterencode(o, _one_shot=True)
  File "C:\Users\pratik\Anaconda3\lib\json\encoder.py", line 257, in iterencode
    return _iterencode(o, 0)
  File "C:\Users\pratik\Anaconda3\lib\json\encoder.py", line 180, in default
    o.__class__.__name__)
TypeError: Object of type 'Response' is not JSON serializable
Exception on /testpost [POST]
Traceback (most recent call last):
  File "C:\Users\pratik\Anaconda3\lib\site-packages\flask\app.py", line 2292, in wsgi_app
    response = self.full_dispatch_request()
  File "C:\Users\pratik\Anaconda3\lib\site-packages\flask\app.py", line 1815, in full_dispatch_request
    rv = self.handle_user_exception(e)
  File "C:\Users\pratik\Anaconda3\lib\site-packages\flask_cors\extension.py", line 161, in wrapped_function
    return cors_after_request(app.make_response(f(*args, **kwargs)))
  File "C:\Users\pratik\Anaconda3\lib\site-packages\flask\app.py", line 1718, in handle_user_exception
    reraise(exc_type, exc_value, tb)
  File "C:\Users\pratik\Anaconda3\lib\site-packages\flask\_compat.py", line 35, in reraise
    raise value
  File "C:\Users\pratik\Anaconda3\lib\site-packages\flask\app.py", line 1813, in full_dispatch_request
    rv = self.dispatch_request()
  File "C:\Users\pratik\Anaconda3\lib\site-packages\flask\app.py", line 1799, in dispatch_request
    return self.view_functions[rule.endpoint](**req.view_args)
  File "api_speedo.py", line 35, in test_post
    print("url",typeof(url))
NameError: name 'typeof' is not defined
Exception on /testpost [POST]
Traceback (most recent call last):
  File "C:\Users\pratik\Anaconda3\lib\site-packages\flask\app.py", line 2292, in wsgi_app
    response = self.full_dispatch_request()
  File "C:\Users\pratik\Anaconda3\lib\site-packages\flask\app.py", line 1815, in full_dispatch_request
    rv = self.handle_user_exception(e)
  File "C:\Users\pratik\Anaconda3\lib\site-packages\flask_cors\extension.py", line 161, in wrapped_function
    return cors_after_request(app.make_response(f(*args, **kwargs)))
  File "C:\Users\pratik\Anaconda3\lib\site-packages\flask\app.py", line 1718, in handle_user_exception
    reraise(exc_type, exc_value, tb)
  File "C:\Users\pratik\Anaconda3\lib\site-packages\flask\_compat.py", line 35, in reraise
    raise value
  File "C:\Users\pratik\Anaconda3\lib\site-packages\flask\app.py", line 1813, in full_dispatch_request
    rv = self.dispatch_request()
  File "C:\Users\pratik\Anaconda3\lib\site-packages\flask\app.py", line 1799, in dispatch_request
    return self.view_functions[rule.endpoint](**req.view_args)
  File "api_speedo.py", line 35, in test_post
    print("url",type(string(url)))
NameError: name 'string' is not defined
Exception on /testpost [POST]
Traceback (most recent call last):
  File "C:\Users\pratik\Anaconda3\lib\site-packages\flask\app.py", line 2292, in wsgi_app
    response = self.full_dispatch_request()
  File "C:\Users\pratik\Anaconda3\lib\site-packages\flask\app.py", line 1815, in full_dispatch_request
    rv = self.handle_user_exception(e)
  File "C:\Users\pratik\Anaconda3\lib\site-packages\flask_cors\extension.py", line 161, in wrapped_function
    return cors_after_request(app.make_response(f(*args, **kwargs)))
  File "C:\Users\pratik\Anaconda3\lib\site-packages\flask\app.py", line 1718, in handle_user_exception
    reraise(exc_type, exc_value, tb)
  File "C:\Users\pratik\Anaconda3\lib\site-packages\flask\_compat.py", line 35, in reraise
    raise value
  File "C:\Users\pratik\Anaconda3\lib\site-packages\flask\app.py", line 1813, in full_dispatch_request
    rv = self.dispatch_request()
  File "C:\Users\pratik\Anaconda3\lib\site-packages\flask\app.py", line 1799, in dispatch_request
    return self.view_functions[rule.endpoint](**req.view_args)
  File "api_speedo.py", line 40, in test_post
    return jsonify(img1)
UnboundLocalError: local variable 'img1' referenced before assignment
Exception on /testpost [POST]
Traceback (most recent call last):
  File "C:\Users\pratik\Anaconda3\lib\site-packages\flask\app.py", line 2292, in wsgi_app
    response = self.full_dispatch_request()
  File "C:\Users\pratik\Anaconda3\lib\site-packages\flask\app.py", line 1815, in full_dispatch_request
    rv = self.handle_user_exception(e)
  File "C:\Users\pratik\Anaconda3\lib\site-packages\flask_cors\extension.py", line 161, in wrapped_function
    return cors_after_request(app.make_response(f(*args, **kwargs)))
  File "C:\Users\pratik\Anaconda3\lib\site-packages\flask\app.py", line 1718, in handle_user_exception
    reraise(exc_type, exc_value, tb)
  File "C:\Users\pratik\Anaconda3\lib\site-packages\flask\_compat.py", line 35, in reraise
    raise value
  File "C:\Users\pratik\Anaconda3\lib\site-packages\flask\app.py", line 1813, in full_dispatch_request
    rv = self.dispatch_request()
  File "C:\Users\pratik\Anaconda3\lib\site-packages\flask\app.py", line 1799, in dispatch_request
    return self.view_functions[rule.endpoint](**req.view_args)
  File "api_speedo.py", line 39, in test_post
    resp = {"data":img1}
UnboundLocalError: local variable 'img1' referenced before assignment
Exception on /testpost [POST]
Traceback (most recent call last):
  File "C:\Users\pratik\Anaconda3\lib\site-packages\flask\app.py", line 2292, in wsgi_app
    response = self.full_dispatch_request()
  File "C:\Users\pratik\Anaconda3\lib\site-packages\flask\app.py", line 1815, in full_dispatch_request
    rv = self.handle_user_exception(e)
  File "C:\Users\pratik\Anaconda3\lib\site-packages\flask_cors\extension.py", line 161, in wrapped_function
    return cors_after_request(app.make_response(f(*args, **kwargs)))
  File "C:\Users\pratik\Anaconda3\lib\site-packages\flask\app.py", line 1718, in handle_user_exception
    reraise(exc_type, exc_value, tb)
  File "C:\Users\pratik\Anaconda3\lib\site-packages\flask\_compat.py", line 35, in reraise
    raise value
  File "C:\Users\pratik\Anaconda3\lib\site-packages\flask\app.py", line 1813, in full_dispatch_request
    rv = self.dispatch_request()
  File "C:\Users\pratik\Anaconda3\lib\site-packages\flask\app.py", line 1799, in dispatch_request
    return self.view_functions[rule.endpoint](**req.view_args)
  File "api_speedo.py", line 43, in test_post
    resp = {"data1":img1 ,"data2":img2,"data3":{'Normal': 0.9539436,
UnboundLocalError: local variable 'img1' referenced before assignment
Exception on /testpost [POST]
Traceback (most recent call last):
  File "C:\Users\pratik\Anaconda3\lib\site-packages\flask\app.py", line 2292, in wsgi_app
    response = self.full_dispatch_request()
  File "C:\Users\pratik\Anaconda3\lib\site-packages\flask\app.py", line 1815, in full_dispatch_request
    rv = self.handle_user_exception(e)
  File "C:\Users\pratik\Anaconda3\lib\site-packages\flask_cors\extension.py", line 161, in wrapped_function
    return cors_after_request(app.make_response(f(*args, **kwargs)))
  File "C:\Users\pratik\Anaconda3\lib\site-packages\flask\app.py", line 1718, in handle_user_exception
    reraise(exc_type, exc_value, tb)
  File "C:\Users\pratik\Anaconda3\lib\site-packages\flask\_compat.py", line 35, in reraise
    raise value
  File "C:\Users\pratik\Anaconda3\lib\site-packages\flask\app.py", line 1813, in full_dispatch_request
    rv = self.dispatch_request()
  File "C:\Users\pratik\Anaconda3\lib\site-packages\flask\app.py", line 1799, in dispatch_request
    return self.view_functions[rule.endpoint](**req.view_args)
  File "api_speedo.py", line 67, in test_post
    resp = {"data1":img1 ,"data2":img2,"data3":img3 ,"data4":img4,"data6":img5,"data7":img6,"data5":{'Normal': 0.9539436,
UnboundLocalError: local variable 'img1' referenced before assignment
Exception on /testpost [POST]
Traceback (most recent call last):
  File "C:\Users\pratik\Anaconda3\lib\site-packages\flask\app.py", line 2292, in wsgi_app
    response = self.full_dispatch_request()
  File "C:\Users\pratik\Anaconda3\lib\site-packages\flask\app.py", line 1815, in full_dispatch_request
    rv = self.handle_user_exception(e)
  File "C:\Users\pratik\Anaconda3\lib\site-packages\flask_cors\extension.py", line 161, in wrapped_function
    return cors_after_request(app.make_response(f(*args, **kwargs)))
  File "C:\Users\pratik\Anaconda3\lib\site-packages\flask\app.py", line 1718, in handle_user_exception
    reraise(exc_type, exc_value, tb)
  File "C:\Users\pratik\Anaconda3\lib\site-packages\flask\_compat.py", line 35, in reraise
    raise value
  File "C:\Users\pratik\Anaconda3\lib\site-packages\flask\app.py", line 1813, in full_dispatch_request
    rv = self.dispatch_request()
  File "C:\Users\pratik\Anaconda3\lib\site-packages\flask\app.py", line 1799, in dispatch_request
    return self.view_functions[rule.endpoint](**req.view_args)
  File "api_speedo.py", line 68, in test_post
    resp = {"data1":img1 ,"data2":img2,"data3":img3 ,"data4":img4,"data6":img5,"data7":img6,"data5":{'Normal': 0.9539436,
UnboundLocalError: local variable 'img1' referenced before assignment
Exception on /testpost [POST]
Traceback (most recent call last):
  File "C:\Users\pratik\Anaconda3\lib\site-packages\flask\app.py", line 2292, in wsgi_app
    response = self.full_dispatch_request()
  File "C:\Users\pratik\Anaconda3\lib\site-packages\flask\app.py", line 1815, in full_dispatch_request
    rv = self.handle_user_exception(e)
  File "C:\Users\pratik\Anaconda3\lib\site-packages\flask_cors\extension.py", line 161, in wrapped_function
    return cors_after_request(app.make_response(f(*args, **kwargs)))
  File "C:\Users\pratik\Anaconda3\lib\site-packages\flask\app.py", line 1718, in handle_user_exception
    reraise(exc_type, exc_value, tb)
  File "C:\Users\pratik\Anaconda3\lib\site-packages\flask\_compat.py", line 35, in reraise
    raise value
  File "C:\Users\pratik\Anaconda3\lib\site-packages\flask\app.py", line 1813, in full_dispatch_request
    rv = self.dispatch_request()
  File "C:\Users\pratik\Anaconda3\lib\site-packages\flask\app.py", line 1799, in dispatch_request
    return self.view_functions[rule.endpoint](**req.view_args)
  File "api_speedo.py", line 79, in test_post
    if filename[-1] == "wear.wav'":
UnboundLocalError: local variable 'resp' referenced before assignment
Exception on /testpost [POST]
Traceback (most recent call last):
  File "C:\Users\pratik\Anaconda3\lib\site-packages\flask\app.py", line 2292, in wsgi_app
    response = self.full_dispatch_request()
  File "C:\Users\pratik\Anaconda3\lib\site-packages\flask\app.py", line 1815, in full_dispatch_request
    rv = self.handle_user_exception(e)
  File "C:\Users\pratik\Anaconda3\lib\site-packages\flask_cors\extension.py", line 161, in wrapped_function
    return cors_after_request(app.make_response(f(*args, **kwargs)))
  File "C:\Users\pratik\Anaconda3\lib\site-packages\flask\app.py", line 1718, in handle_user_exception
    reraise(exc_type, exc_value, tb)
  File "C:\Users\pratik\Anaconda3\lib\site-packages\flask\_compat.py", line 35, in reraise
    raise value
  File "C:\Users\pratik\Anaconda3\lib\site-packages\flask\app.py", line 1813, in full_dispatch_request
    rv = self.dispatch_request()
  File "C:\Users\pratik\Anaconda3\lib\site-packages\flask\app.py", line 1799, in dispatch_request
    return self.view_functions[rule.endpoint](**req.view_args)
  File "api_speedo.py", line 89, in test_post
    return jsonify(resp)
  File "C:\Users\pratik\Anaconda3\lib\site-packages\flask\json\__init__.py", line 321, in jsonify
    dumps(data, indent=indent, separators=separators) + '\n',
  File "C:\Users\pratik\Anaconda3\lib\site-packages\flask\json\__init__.py", line 179, in dumps
    rv = _json.dumps(obj, **kwargs)
  File "C:\Users\pratik\Anaconda3\lib\site-packages\simplejson\__init__.py", line 399, in dumps
    **kw).encode(obj)
  File "C:\Users\pratik\Anaconda3\lib\site-packages\simplejson\encoder.py", line 296, in encode
    chunks = self.iterencode(o, _one_shot=True)
  File "C:\Users\pratik\Anaconda3\lib\site-packages\simplejson\encoder.py", line 378, in iterencode
    return _iterencode(o, 0)
  File "C:\Users\pratik\Anaconda3\lib\site-packages\flask\json\__init__.py", line 81, in default
    return _json.JSONEncoder.default(self, o)
  File "C:\Users\pratik\Anaconda3\lib\site-packages\simplejson\encoder.py", line 273, in default
    o.__class__.__name__)
TypeError: Object of type ndarray is not JSON serializable
Exception on /testpost [POST]
Traceback (most recent call last):
  File "C:\Users\pratik\Anaconda3\lib\site-packages\flask\app.py", line 2292, in wsgi_app
    response = self.full_dispatch_request()
  File "C:\Users\pratik\Anaconda3\lib\site-packages\flask\app.py", line 1815, in full_dispatch_request
    rv = self.handle_user_exception(e)
  File "C:\Users\pratik\Anaconda3\lib\site-packages\flask_cors\extension.py", line 161, in wrapped_function
    return cors_after_request(app.make_response(f(*args, **kwargs)))
  File "C:\Users\pratik\Anaconda3\lib\site-packages\flask\app.py", line 1718, in handle_user_exception
    reraise(exc_type, exc_value, tb)
  File "C:\Users\pratik\Anaconda3\lib\site-packages\flask\_compat.py", line 35, in reraise
    raise value
  File "C:\Users\pratik\Anaconda3\lib\site-packages\flask\app.py", line 1813, in full_dispatch_request
    rv = self.dispatch_request()
  File "C:\Users\pratik\Anaconda3\lib\site-packages\flask\app.py", line 1799, in dispatch_request
    return self.view_functions[rule.endpoint](**req.view_args)
  File "api_speedo.py", line 89, in test_post
    return jsonify(resp)
  File "C:\Users\pratik\Anaconda3\lib\site-packages\flask\json\__init__.py", line 321, in jsonify
    dumps(data, indent=indent, separators=separators) + '\n',
  File "C:\Users\pratik\Anaconda3\lib\site-packages\flask\json\__init__.py", line 179, in dumps
    rv = _json.dumps(obj, **kwargs)
  File "C:\Users\pratik\Anaconda3\lib\site-packages\simplejson\__init__.py", line 399, in dumps
    **kw).encode(obj)
  File "C:\Users\pratik\Anaconda3\lib\site-packages\simplejson\encoder.py", line 296, in encode
    chunks = self.iterencode(o, _one_shot=True)
  File "C:\Users\pratik\Anaconda3\lib\site-packages\simplejson\encoder.py", line 378, in iterencode
    return _iterencode(o, 0)
  File "C:\Users\pratik\Anaconda3\lib\site-packages\flask\json\__init__.py", line 81, in default
    return _json.JSONEncoder.default(self, o)
  File "C:\Users\pratik\Anaconda3\lib\site-packages\simplejson\encoder.py", line 273, in default
    o.__class__.__name__)
TypeError: Object of type ndarray is not JSON serializable
Exception on /testpost [POST]
Traceback (most recent call last):
  File "C:\Users\pratik\Anaconda3\lib\site-packages\flask\app.py", line 2292, in wsgi_app
    response = self.full_dispatch_request()
  File "C:\Users\pratik\Anaconda3\lib\site-packages\flask\app.py", line 1815, in full_dispatch_request
    rv = self.handle_user_exception(e)
  File "C:\Users\pratik\Anaconda3\lib\site-packages\flask_cors\extension.py", line 161, in wrapped_function
    return cors_after_request(app.make_response(f(*args, **kwargs)))
  File "C:\Users\pratik\Anaconda3\lib\site-packages\flask\app.py", line 1718, in handle_user_exception
    reraise(exc_type, exc_value, tb)
  File "C:\Users\pratik\Anaconda3\lib\site-packages\flask\_compat.py", line 35, in reraise
    raise value
  File "C:\Users\pratik\Anaconda3\lib\site-packages\flask\app.py", line 1813, in full_dispatch_request
    rv = self.dispatch_request()
  File "C:\Users\pratik\Anaconda3\lib\site-packages\flask\app.py", line 1799, in dispatch_request
    return self.view_functions[rule.endpoint](**req.view_args)
  File "api_speedo.py", line 89, in test_post
    return jsonify(resp)
  File "C:\Users\pratik\Anaconda3\lib\site-packages\flask\json\__init__.py", line 321, in jsonify
    dumps(data, indent=indent, separators=separators) + '\n',
  File "C:\Users\pratik\Anaconda3\lib\site-packages\flask\json\__init__.py", line 179, in dumps
    rv = _json.dumps(obj, **kwargs)
  File "C:\Users\pratik\Anaconda3\lib\site-packages\simplejson\__init__.py", line 399, in dumps
    **kw).encode(obj)
  File "C:\Users\pratik\Anaconda3\lib\site-packages\simplejson\encoder.py", line 296, in encode
    chunks = self.iterencode(o, _one_shot=True)
  File "C:\Users\pratik\Anaconda3\lib\site-packages\simplejson\encoder.py", line 378, in iterencode
    return _iterencode(o, 0)
  File "C:\Users\pratik\Anaconda3\lib\site-packages\flask\json\__init__.py", line 81, in default
    return _json.JSONEncoder.default(self, o)
  File "C:\Users\pratik\Anaconda3\lib\site-packages\simplejson\encoder.py", line 273, in default
    o.__class__.__name__)
TypeError: Object of type ndarray is not JSON serializable
Exception on /testpost [POST]
Traceback (most recent call last):
  File "C:\Users\pratik\Anaconda3\lib\site-packages\flask\app.py", line 2292, in wsgi_app
    response = self.full_dispatch_request()
  File "C:\Users\pratik\Anaconda3\lib\site-packages\flask\app.py", line 1815, in full_dispatch_request
    rv = self.handle_user_exception(e)
  File "C:\Users\pratik\Anaconda3\lib\site-packages\flask_cors\extension.py", line 161, in wrapped_function
    return cors_after_request(app.make_response(f(*args, **kwargs)))
  File "C:\Users\pratik\Anaconda3\lib\site-packages\flask\app.py", line 1718, in handle_user_exception
    reraise(exc_type, exc_value, tb)
  File "C:\Users\pratik\Anaconda3\lib\site-packages\flask\_compat.py", line 35, in reraise
    raise value
  File "C:\Users\pratik\Anaconda3\lib\site-packages\flask\app.py", line 1813, in full_dispatch_request
    rv = self.dispatch_request()
  File "C:\Users\pratik\Anaconda3\lib\site-packages\flask\app.py", line 1799, in dispatch_request
    return self.view_functions[rule.endpoint](**req.view_args)
  File "api_speedo.py", line 89, in test_post
    return jsonify(resp)
  File "C:\Users\pratik\Anaconda3\lib\site-packages\flask\json\__init__.py", line 321, in jsonify
    dumps(data, indent=indent, separators=separators) + '\n',
  File "C:\Users\pratik\Anaconda3\lib\site-packages\flask\json\__init__.py", line 179, in dumps
    rv = _json.dumps(obj, **kwargs)
  File "C:\Users\pratik\Anaconda3\lib\site-packages\simplejson\__init__.py", line 399, in dumps
    **kw).encode(obj)
  File "C:\Users\pratik\Anaconda3\lib\site-packages\simplejson\encoder.py", line 296, in encode
    chunks = self.iterencode(o, _one_shot=True)
  File "C:\Users\pratik\Anaconda3\lib\site-packages\simplejson\encoder.py", line 378, in iterencode
    return _iterencode(o, 0)
  File "C:\Users\pratik\Anaconda3\lib\site-packages\flask\json\__init__.py", line 81, in default
    return _json.JSONEncoder.default(self, o)
  File "C:\Users\pratik\Anaconda3\lib\site-packages\simplejson\encoder.py", line 273, in default
    o.__class__.__name__)
TypeError: Object of type ndarray is not JSON serializable
Exception on /testpost [POST]
Traceback (most recent call last):
  File "C:\Users\pratik\Anaconda3\lib\site-packages\flask\app.py", line 2292, in wsgi_app
    response = self.full_dispatch_request()
  File "C:\Users\pratik\Anaconda3\lib\site-packages\flask\app.py", line 1815, in full_dispatch_request
    rv = self.handle_user_exception(e)
  File "C:\Users\pratik\Anaconda3\lib\site-packages\flask_cors\extension.py", line 161, in wrapped_function
    return cors_after_request(app.make_response(f(*args, **kwargs)))
  File "C:\Users\pratik\Anaconda3\lib\site-packages\flask\app.py", line 1718, in handle_user_exception
    reraise(exc_type, exc_value, tb)
  File "C:\Users\pratik\Anaconda3\lib\site-packages\flask\_compat.py", line 35, in reraise
    raise value
  File "C:\Users\pratik\Anaconda3\lib\site-packages\flask\app.py", line 1813, in full_dispatch_request
    rv = self.dispatch_request()
  File "C:\Users\pratik\Anaconda3\lib\site-packages\flask\app.py", line 1799, in dispatch_request
    return self.view_functions[rule.endpoint](**req.view_args)
  File "api_speedo.py", line 56, in test_post
    pickled_dumped = pickle.dumps(rgb_image, protocol=2)
NameError: name 'rgb_image' is not defined
Exception on /testpost [POST]
Traceback (most recent call last):
  File "C:\Users\pratik\Anaconda3\lib\site-packages\flask\app.py", line 2292, in wsgi_app
    response = self.full_dispatch_request()
  File "C:\Users\pratik\Anaconda3\lib\site-packages\flask\app.py", line 1815, in full_dispatch_request
    rv = self.handle_user_exception(e)
  File "C:\Users\pratik\Anaconda3\lib\site-packages\flask_cors\extension.py", line 161, in wrapped_function
    return cors_after_request(app.make_response(f(*args, **kwargs)))
  File "C:\Users\pratik\Anaconda3\lib\site-packages\flask\app.py", line 1718, in handle_user_exception
    reraise(exc_type, exc_value, tb)
  File "C:\Users\pratik\Anaconda3\lib\site-packages\flask\_compat.py", line 35, in reraise
    raise value
  File "C:\Users\pratik\Anaconda3\lib\site-packages\flask\app.py", line 1813, in full_dispatch_request
    rv = self.dispatch_request()
  File "C:\Users\pratik\Anaconda3\lib\site-packages\flask\app.py", line 1799, in dispatch_request
    return self.view_functions[rule.endpoint](**req.view_args)
  File "api_speedo.py", line 91, in test_post
    return jsonify(resp)
  File "C:\Users\pratik\Anaconda3\lib\site-packages\flask\json\__init__.py", line 321, in jsonify
    dumps(data, indent=indent, separators=separators) + '\n',
  File "C:\Users\pratik\Anaconda3\lib\site-packages\flask\json\__init__.py", line 179, in dumps
    rv = _json.dumps(obj, **kwargs)
  File "C:\Users\pratik\Anaconda3\lib\site-packages\simplejson\__init__.py", line 399, in dumps
    **kw).encode(obj)
  File "C:\Users\pratik\Anaconda3\lib\site-packages\simplejson\encoder.py", line 296, in encode
    chunks = self.iterencode(o, _one_shot=True)
  File "C:\Users\pratik\Anaconda3\lib\site-packages\simplejson\encoder.py", line 378, in iterencode
    return _iterencode(o, 0)
UnicodeDecodeError: 'utf-8' codec can't decode byte 0x80 in position 0: invalid start byte
Exception on /testpost [POST]
Traceback (most recent call last):
  File "C:\Users\pratik\Anaconda3\lib\site-packages\flask\app.py", line 2292, in wsgi_app
    response = self.full_dispatch_request()
  File "C:\Users\pratik\Anaconda3\lib\site-packages\flask\app.py", line 1815, in full_dispatch_request
    rv = self.handle_user_exception(e)
  File "C:\Users\pratik\Anaconda3\lib\site-packages\flask_cors\extension.py", line 161, in wrapped_function
    return cors_after_request(app.make_response(f(*args, **kwargs)))
  File "C:\Users\pratik\Anaconda3\lib\site-packages\flask\app.py", line 1718, in handle_user_exception
    reraise(exc_type, exc_value, tb)
  File "C:\Users\pratik\Anaconda3\lib\site-packages\flask\_compat.py", line 35, in reraise
    raise value
  File "C:\Users\pratik\Anaconda3\lib\site-packages\flask\app.py", line 1813, in full_dispatch_request
    rv = self.dispatch_request()
  File "C:\Users\pratik\Anaconda3\lib\site-packages\flask\app.py", line 1799, in dispatch_request
    return self.view_functions[rule.endpoint](**req.view_args)
  File "api_speedo.py", line 93, in test_post
    return jsonify(resp)
  File "C:\Users\pratik\Anaconda3\lib\site-packages\flask\json\__init__.py", line 321, in jsonify
    dumps(data, indent=indent, separators=separators) + '\n',
  File "C:\Users\pratik\Anaconda3\lib\site-packages\flask\json\__init__.py", line 179, in dumps
    rv = _json.dumps(obj, **kwargs)
  File "C:\Users\pratik\Anaconda3\lib\site-packages\simplejson\__init__.py", line 399, in dumps
    **kw).encode(obj)
  File "C:\Users\pratik\Anaconda3\lib\site-packages\simplejson\encoder.py", line 296, in encode
    chunks = self.iterencode(o, _one_shot=True)
  File "C:\Users\pratik\Anaconda3\lib\site-packages\simplejson\encoder.py", line 378, in iterencode
    return _iterencode(o, 0)
  File "C:\Users\pratik\Anaconda3\lib\site-packages\flask\json\__init__.py", line 81, in default
    return _json.JSONEncoder.default(self, o)
  File "C:\Users\pratik\Anaconda3\lib\site-packages\simplejson\encoder.py", line 273, in default
    o.__class__.__name__)
TypeError: Object of type ndarray is not JSON serializable
Exception on /testpost [POST]
Traceback (most recent call last):
  File "C:\Users\pratik\Anaconda3\lib\site-packages\flask\app.py", line 2292, in wsgi_app
    response = self.full_dispatch_request()
  File "C:\Users\pratik\Anaconda3\lib\site-packages\flask\app.py", line 1815, in full_dispatch_request
    rv = self.handle_user_exception(e)
  File "C:\Users\pratik\Anaconda3\lib\site-packages\flask_cors\extension.py", line 161, in wrapped_function
    return cors_after_request(app.make_response(f(*args, **kwargs)))
  File "C:\Users\pratik\Anaconda3\lib\site-packages\flask\app.py", line 1718, in handle_user_exception
    reraise(exc_type, exc_value, tb)
  File "C:\Users\pratik\Anaconda3\lib\site-packages\flask\_compat.py", line 35, in reraise
    raise value
  File "C:\Users\pratik\Anaconda3\lib\site-packages\flask\app.py", line 1813, in full_dispatch_request
    rv = self.dispatch_request()
  File "C:\Users\pratik\Anaconda3\lib\site-packages\flask\app.py", line 1799, in dispatch_request
    return self.view_functions[rule.endpoint](**req.view_args)
  File "api_speedo.py", line 93, in test_post
    return jsonify(resp)
  File "C:\Users\pratik\Anaconda3\lib\site-packages\flask\json\__init__.py", line 321, in jsonify
    dumps(data, indent=indent, separators=separators) + '\n',
  File "C:\Users\pratik\Anaconda3\lib\site-packages\flask\json\__init__.py", line 179, in dumps
    rv = _json.dumps(obj, **kwargs)
  File "C:\Users\pratik\Anaconda3\lib\site-packages\simplejson\__init__.py", line 399, in dumps
    **kw).encode(obj)
  File "C:\Users\pratik\Anaconda3\lib\site-packages\simplejson\encoder.py", line 296, in encode
    chunks = self.iterencode(o, _one_shot=True)
  File "C:\Users\pratik\Anaconda3\lib\site-packages\simplejson\encoder.py", line 378, in iterencode
    return _iterencode(o, 0)
  File "C:\Users\pratik\Anaconda3\lib\site-packages\flask\json\__init__.py", line 81, in default
    return _json.JSONEncoder.default(self, o)
  File "C:\Users\pratik\Anaconda3\lib\site-packages\simplejson\encoder.py", line 273, in default
    o.__class__.__name__)
TypeError: Object of type ndarray is not JSON serializable
Exception on /testpost [POST]
Traceback (most recent call last):
  File "C:\Users\pratik\Anaconda3\lib\site-packages\flask\app.py", line 2292, in wsgi_app
    response = self.full_dispatch_request()
  File "C:\Users\pratik\Anaconda3\lib\site-packages\flask\app.py", line 1815, in full_dispatch_request
    rv = self.handle_user_exception(e)
  File "C:\Users\pratik\Anaconda3\lib\site-packages\flask_cors\extension.py", line 161, in wrapped_function
    return cors_after_request(app.make_response(f(*args, **kwargs)))
  File "C:\Users\pratik\Anaconda3\lib\site-packages\flask\app.py", line 1718, in handle_user_exception
    reraise(exc_type, exc_value, tb)
  File "C:\Users\pratik\Anaconda3\lib\site-packages\flask\_compat.py", line 35, in reraise
    raise value
  File "C:\Users\pratik\Anaconda3\lib\site-packages\flask\app.py", line 1813, in full_dispatch_request
    rv = self.dispatch_request()
  File "C:\Users\pratik\Anaconda3\lib\site-packages\flask\app.py", line 1799, in dispatch_request
    return self.view_functions[rule.endpoint](**req.view_args)
  File "api_speedo.py", line 93, in test_post
    return jsonify(resp)
  File "C:\Users\pratik\Anaconda3\lib\site-packages\flask\json\__init__.py", line 321, in jsonify
    dumps(data, indent=indent, separators=separators) + '\n',
  File "C:\Users\pratik\Anaconda3\lib\site-packages\flask\json\__init__.py", line 179, in dumps
    rv = _json.dumps(obj, **kwargs)
  File "C:\Users\pratik\Anaconda3\lib\site-packages\simplejson\__init__.py", line 399, in dumps
    **kw).encode(obj)
  File "C:\Users\pratik\Anaconda3\lib\site-packages\simplejson\encoder.py", line 296, in encode
    chunks = self.iterencode(o, _one_shot=True)
  File "C:\Users\pratik\Anaconda3\lib\site-packages\simplejson\encoder.py", line 378, in iterencode
    return _iterencode(o, 0)
  File "C:\Users\pratik\Anaconda3\lib\site-packages\flask\json\__init__.py", line 81, in default
    return _json.JSONEncoder.default(self, o)
  File "C:\Users\pratik\Anaconda3\lib\site-packages\simplejson\encoder.py", line 273, in default
    o.__class__.__name__)
TypeError: Object of type int16 is not JSON serializable
Exception on /testpost [POST]
Traceback (most recent call last):
  File "C:\Users\pratik\Anaconda3\lib\site-packages\flask\app.py", line 2292, in wsgi_app
    response = self.full_dispatch_request()
  File "C:\Users\pratik\Anaconda3\lib\site-packages\flask\app.py", line 1815, in full_dispatch_request
    rv = self.handle_user_exception(e)
  File "C:\Users\pratik\Anaconda3\lib\site-packages\flask_cors\extension.py", line 161, in wrapped_function
    return cors_after_request(app.make_response(f(*args, **kwargs)))
  File "C:\Users\pratik\Anaconda3\lib\site-packages\flask\app.py", line 1718, in handle_user_exception
    reraise(exc_type, exc_value, tb)
  File "C:\Users\pratik\Anaconda3\lib\site-packages\flask\_compat.py", line 35, in reraise
    raise value
  File "C:\Users\pratik\Anaconda3\lib\site-packages\flask\app.py", line 1813, in full_dispatch_request
    rv = self.dispatch_request()
  File "C:\Users\pratik\Anaconda3\lib\site-packages\flask\app.py", line 1799, in dispatch_request
    return self.view_functions[rule.endpoint](**req.view_args)
  File "api_speedo.py", line 93, in test_post
    return jsonify(resp)
  File "C:\Users\pratik\Anaconda3\lib\site-packages\flask\json\__init__.py", line 321, in jsonify
    dumps(data, indent=indent, separators=separators) + '\n',
  File "C:\Users\pratik\Anaconda3\lib\site-packages\flask\json\__init__.py", line 179, in dumps
    rv = _json.dumps(obj, **kwargs)
  File "C:\Users\pratik\Anaconda3\lib\site-packages\simplejson\__init__.py", line 399, in dumps
    **kw).encode(obj)
  File "C:\Users\pratik\Anaconda3\lib\site-packages\simplejson\encoder.py", line 296, in encode
    chunks = self.iterencode(o, _one_shot=True)
  File "C:\Users\pratik\Anaconda3\lib\site-packages\simplejson\encoder.py", line 378, in iterencode
    return _iterencode(o, 0)
  File "C:\Users\pratik\Anaconda3\lib\site-packages\flask\json\__init__.py", line 81, in default
    return _json.JSONEncoder.default(self, o)
  File "C:\Users\pratik\Anaconda3\lib\site-packages\simplejson\encoder.py", line 273, in default
    o.__class__.__name__)
TypeError: Object of type int16 is not JSON serializable
Exception on /testpost [POST]
Traceback (most recent call last):
  File "C:\Users\pratik\Anaconda3\lib\site-packages\flask\app.py", line 2292, in wsgi_app
    response = self.full_dispatch_request()
  File "C:\Users\pratik\Anaconda3\lib\site-packages\flask\app.py", line 1815, in full_dispatch_request
    rv = self.handle_user_exception(e)
  File "C:\Users\pratik\Anaconda3\lib\site-packages\flask_cors\extension.py", line 161, in wrapped_function
    return cors_after_request(app.make_response(f(*args, **kwargs)))
  File "C:\Users\pratik\Anaconda3\lib\site-packages\flask\app.py", line 1718, in handle_user_exception
    reraise(exc_type, exc_value, tb)
  File "C:\Users\pratik\Anaconda3\lib\site-packages\flask\_compat.py", line 35, in reraise
    raise value
  File "C:\Users\pratik\Anaconda3\lib\site-packages\flask\app.py", line 1813, in full_dispatch_request
    rv = self.dispatch_request()
  File "C:\Users\pratik\Anaconda3\lib\site-packages\flask\app.py", line 1799, in dispatch_request
    return self.view_functions[rule.endpoint](**req.view_args)
  File "api_speedo.py", line 65, in test_post
    resp = {"data1":img1 ,"data2":img2,"data3":img3 ,"data4":img4,"data6":img5,"data7":img6,"data5":list.tolist()	 }
AttributeError: 'list' object has no attribute 'tolist'
Exception on /testpost [POST]
Traceback (most recent call last):
  File "C:\Users\pratik\Anaconda3\lib\site-packages\flask\app.py", line 2292, in wsgi_app
    response = self.full_dispatch_request()
  File "C:\Users\pratik\Anaconda3\lib\site-packages\flask\app.py", line 1815, in full_dispatch_request
    rv = self.handle_user_exception(e)
  File "C:\Users\pratik\Anaconda3\lib\site-packages\flask_cors\extension.py", line 161, in wrapped_function
    return cors_after_request(app.make_response(f(*args, **kwargs)))
  File "C:\Users\pratik\Anaconda3\lib\site-packages\flask\app.py", line 1718, in handle_user_exception
    reraise(exc_type, exc_value, tb)
  File "C:\Users\pratik\Anaconda3\lib\site-packages\flask\_compat.py", line 35, in reraise
    raise value
  File "C:\Users\pratik\Anaconda3\lib\site-packages\flask\app.py", line 1813, in full_dispatch_request
    rv = self.dispatch_request()
  File "C:\Users\pratik\Anaconda3\lib\site-packages\flask\app.py", line 1799, in dispatch_request
    return self.view_functions[rule.endpoint](**req.view_args)
  File "api_speedo.py", line 93, in test_post
    return jsonify(resp)
  File "C:\Users\pratik\Anaconda3\lib\site-packages\flask\json\__init__.py", line 321, in jsonify
    dumps(data, indent=indent, separators=separators) + '\n',
  File "C:\Users\pratik\Anaconda3\lib\site-packages\flask\json\__init__.py", line 179, in dumps
    rv = _json.dumps(obj, **kwargs)
  File "C:\Users\pratik\Anaconda3\lib\site-packages\simplejson\__init__.py", line 399, in dumps
    **kw).encode(obj)
  File "C:\Users\pratik\Anaconda3\lib\site-packages\simplejson\encoder.py", line 296, in encode
    chunks = self.iterencode(o, _one_shot=True)
  File "C:\Users\pratik\Anaconda3\lib\site-packages\simplejson\encoder.py", line 378, in iterencode
    return _iterencode(o, 0)
  File "C:\Users\pratik\Anaconda3\lib\site-packages\flask\json\__init__.py", line 81, in default
    return _json.JSONEncoder.default(self, o)
  File "C:\Users\pratik\Anaconda3\lib\site-packages\simplejson\encoder.py", line 273, in default
    o.__class__.__name__)
TypeError: Object of type int16 is not JSON serializable
Exception on /testpost [POST]
Traceback (most recent call last):
  File "C:\Users\pratik\Anaconda3\lib\site-packages\flask\app.py", line 2292, in wsgi_app
    response = self.full_dispatch_request()
  File "C:\Users\pratik\Anaconda3\lib\site-packages\flask\app.py", line 1815, in full_dispatch_request
    rv = self.handle_user_exception(e)
  File "C:\Users\pratik\Anaconda3\lib\site-packages\flask_cors\extension.py", line 161, in wrapped_function
    return cors_after_request(app.make_response(f(*args, **kwargs)))
  File "C:\Users\pratik\Anaconda3\lib\site-packages\flask\app.py", line 1718, in handle_user_exception
    reraise(exc_type, exc_value, tb)
  File "C:\Users\pratik\Anaconda3\lib\site-packages\flask\_compat.py", line 35, in reraise
    raise value
  File "C:\Users\pratik\Anaconda3\lib\site-packages\flask\app.py", line 1813, in full_dispatch_request
    rv = self.dispatch_request()
  File "C:\Users\pratik\Anaconda3\lib\site-packages\flask\app.py", line 1799, in dispatch_request
    return self.view_functions[rule.endpoint](**req.view_args)
  File "api_speedo.py", line 93, in test_post
    return jsonify(resp)
  File "C:\Users\pratik\Anaconda3\lib\site-packages\flask\json\__init__.py", line 321, in jsonify
    dumps(data, indent=indent, separators=separators) + '\n',
  File "C:\Users\pratik\Anaconda3\lib\site-packages\flask\json\__init__.py", line 179, in dumps
    rv = _json.dumps(obj, **kwargs)
  File "C:\Users\pratik\Anaconda3\lib\site-packages\simplejson\__init__.py", line 399, in dumps
    **kw).encode(obj)
  File "C:\Users\pratik\Anaconda3\lib\site-packages\simplejson\encoder.py", line 296, in encode
    chunks = self.iterencode(o, _one_shot=True)
  File "C:\Users\pratik\Anaconda3\lib\site-packages\simplejson\encoder.py", line 378, in iterencode
    return _iterencode(o, 0)
  File "C:\Users\pratik\Anaconda3\lib\site-packages\flask\json\__init__.py", line 81, in default
    return _json.JSONEncoder.default(self, o)
  File "C:\Users\pratik\Anaconda3\lib\site-packages\simplejson\encoder.py", line 273, in default
    o.__class__.__name__)
TypeError: Object of type int16 is not JSON serializable
Exception on /testpost [POST]
Traceback (most recent call last):
  File "C:\Users\pratik\Anaconda3\lib\site-packages\flask\app.py", line 2292, in wsgi_app
    response = self.full_dispatch_request()
  File "C:\Users\pratik\Anaconda3\lib\site-packages\flask\app.py", line 1815, in full_dispatch_request
    rv = self.handle_user_exception(e)
  File "C:\Users\pratik\Anaconda3\lib\site-packages\flask_cors\extension.py", line 161, in wrapped_function
    return cors_after_request(app.make_response(f(*args, **kwargs)))
  File "C:\Users\pratik\Anaconda3\lib\site-packages\flask\app.py", line 1718, in handle_user_exception
    reraise(exc_type, exc_value, tb)
  File "C:\Users\pratik\Anaconda3\lib\site-packages\flask\_compat.py", line 35, in reraise
    raise value
  File "C:\Users\pratik\Anaconda3\lib\site-packages\flask\app.py", line 1813, in full_dispatch_request
    rv = self.dispatch_request()
  File "C:\Users\pratik\Anaconda3\lib\site-packages\flask\app.py", line 1799, in dispatch_request
    return self.view_functions[rule.endpoint](**req.view_args)
  File "api_speedo.py", line 93, in test_post
    return jsonify(resp)
  File "C:\Users\pratik\Anaconda3\lib\site-packages\flask\json\__init__.py", line 321, in jsonify
    dumps(data, indent=indent, separators=separators) + '\n',
  File "C:\Users\pratik\Anaconda3\lib\site-packages\flask\json\__init__.py", line 179, in dumps
    rv = _json.dumps(obj, **kwargs)
  File "C:\Users\pratik\Anaconda3\lib\site-packages\simplejson\__init__.py", line 399, in dumps
    **kw).encode(obj)
  File "C:\Users\pratik\Anaconda3\lib\site-packages\simplejson\encoder.py", line 296, in encode
    chunks = self.iterencode(o, _one_shot=True)
  File "C:\Users\pratik\Anaconda3\lib\site-packages\simplejson\encoder.py", line 378, in iterencode
    return _iterencode(o, 0)
  File "C:\Users\pratik\Anaconda3\lib\site-packages\flask\json\__init__.py", line 81, in default
    return _json.JSONEncoder.default(self, o)
  File "C:\Users\pratik\Anaconda3\lib\site-packages\simplejson\encoder.py", line 273, in default
    o.__class__.__name__)
TypeError: Object of type int16 is not JSON serializable
Exception on /testpost [POST]
Traceback (most recent call last):
  File "C:\Users\pratik\Anaconda3\lib\site-packages\flask\app.py", line 2292, in wsgi_app
    response = self.full_dispatch_request()
  File "C:\Users\pratik\Anaconda3\lib\site-packages\flask\app.py", line 1815, in full_dispatch_request
    rv = self.handle_user_exception(e)
  File "C:\Users\pratik\Anaconda3\lib\site-packages\flask_cors\extension.py", line 161, in wrapped_function
    return cors_after_request(app.make_response(f(*args, **kwargs)))
  File "C:\Users\pratik\Anaconda3\lib\site-packages\flask\app.py", line 1718, in handle_user_exception
    reraise(exc_type, exc_value, tb)
  File "C:\Users\pratik\Anaconda3\lib\site-packages\flask\_compat.py", line 35, in reraise
    raise value
  File "C:\Users\pratik\Anaconda3\lib\site-packages\flask\app.py", line 1813, in full_dispatch_request
    rv = self.dispatch_request()
  File "C:\Users\pratik\Anaconda3\lib\site-packages\flask\app.py", line 1799, in dispatch_request
    return self.view_functions[rule.endpoint](**req.view_args)
  File "api_speedo.py", line 94, in test_post
    return jsonify(resp)
  File "C:\Users\pratik\Anaconda3\lib\site-packages\flask\json\__init__.py", line 321, in jsonify
    dumps(data, indent=indent, separators=separators) + '\n',
  File "C:\Users\pratik\Anaconda3\lib\site-packages\flask\json\__init__.py", line 179, in dumps
    rv = _json.dumps(obj, **kwargs)
  File "C:\Users\pratik\Anaconda3\lib\site-packages\simplejson\__init__.py", line 399, in dumps
    **kw).encode(obj)
  File "C:\Users\pratik\Anaconda3\lib\site-packages\simplejson\encoder.py", line 296, in encode
    chunks = self.iterencode(o, _one_shot=True)
  File "C:\Users\pratik\Anaconda3\lib\site-packages\simplejson\encoder.py", line 378, in iterencode
    return _iterencode(o, 0)
UnicodeDecodeError: 'utf-8' codec can't decode byte 0x80 in position 0: invalid start byte
Exception on /testpost [POST]
Traceback (most recent call last):
  File "C:\Users\pratik\Anaconda3\lib\site-packages\flask\app.py", line 2292, in wsgi_app
    response = self.full_dispatch_request()
  File "C:\Users\pratik\Anaconda3\lib\site-packages\flask\app.py", line 1815, in full_dispatch_request
    rv = self.handle_user_exception(e)
  File "C:\Users\pratik\Anaconda3\lib\site-packages\flask_cors\extension.py", line 161, in wrapped_function
    return cors_after_request(app.make_response(f(*args, **kwargs)))
  File "C:\Users\pratik\Anaconda3\lib\site-packages\flask\app.py", line 1718, in handle_user_exception
    reraise(exc_type, exc_value, tb)
  File "C:\Users\pratik\Anaconda3\lib\site-packages\flask\_compat.py", line 35, in reraise
    raise value
  File "C:\Users\pratik\Anaconda3\lib\site-packages\flask\app.py", line 1813, in full_dispatch_request
    rv = self.dispatch_request()
  File "C:\Users\pratik\Anaconda3\lib\site-packages\flask\app.py", line 1799, in dispatch_request
    return self.view_functions[rule.endpoint](**req.view_args)
  File "api_speedo.py", line 62, in test_post
    resp['data5'] = list1
UnboundLocalError: local variable 'resp' referenced before assignment
Exception on /testpost [POST]
Traceback (most recent call last):
  File "C:\Users\pratik\Anaconda3\lib\site-packages\flask\app.py", line 2292, in wsgi_app
    response = self.full_dispatch_request()
  File "C:\Users\pratik\Anaconda3\lib\site-packages\flask\app.py", line 1815, in full_dispatch_request
    rv = self.handle_user_exception(e)
  File "C:\Users\pratik\Anaconda3\lib\site-packages\flask_cors\extension.py", line 161, in wrapped_function
    return cors_after_request(app.make_response(f(*args, **kwargs)))
  File "C:\Users\pratik\Anaconda3\lib\site-packages\flask\app.py", line 1718, in handle_user_exception
    reraise(exc_type, exc_value, tb)
  File "C:\Users\pratik\Anaconda3\lib\site-packages\flask\_compat.py", line 35, in reraise
    raise value
  File "C:\Users\pratik\Anaconda3\lib\site-packages\flask\app.py", line 1813, in full_dispatch_request
    rv = self.dispatch_request()
  File "C:\Users\pratik\Anaconda3\lib\site-packages\flask\app.py", line 1799, in dispatch_request
    return self.view_functions[rule.endpoint](**req.view_args)
  File "api_speedo.py", line 95, in test_post
    return jsonify(resp)
  File "C:\Users\pratik\Anaconda3\lib\site-packages\flask\json\__init__.py", line 321, in jsonify
    dumps(data, indent=indent, separators=separators) + '\n',
  File "C:\Users\pratik\Anaconda3\lib\site-packages\flask\json\__init__.py", line 179, in dumps
    rv = _json.dumps(obj, **kwargs)
  File "C:\Users\pratik\Anaconda3\lib\site-packages\simplejson\__init__.py", line 399, in dumps
    **kw).encode(obj)
  File "C:\Users\pratik\Anaconda3\lib\site-packages\simplejson\encoder.py", line 296, in encode
    chunks = self.iterencode(o, _one_shot=True)
  File "C:\Users\pratik\Anaconda3\lib\site-packages\simplejson\encoder.py", line 378, in iterencode
    return _iterencode(o, 0)
  File "C:\Users\pratik\Anaconda3\lib\site-packages\flask\json\__init__.py", line 81, in default
    return _json.JSONEncoder.default(self, o)
  File "C:\Users\pratik\Anaconda3\lib\site-packages\simplejson\encoder.py", line 273, in default
    o.__class__.__name__)
TypeError: Object of type int16 is not JSON serializable
Exception on /testpost [POST]
Traceback (most recent call last):
  File "C:\Users\pratik\Anaconda3\lib\site-packages\flask\app.py", line 2292, in wsgi_app
    response = self.full_dispatch_request()
  File "C:\Users\pratik\Anaconda3\lib\site-packages\flask\app.py", line 1815, in full_dispatch_request
    rv = self.handle_user_exception(e)
  File "C:\Users\pratik\Anaconda3\lib\site-packages\flask_cors\extension.py", line 161, in wrapped_function
    return cors_after_request(app.make_response(f(*args, **kwargs)))
  File "C:\Users\pratik\Anaconda3\lib\site-packages\flask\app.py", line 1718, in handle_user_exception
    reraise(exc_type, exc_value, tb)
  File "C:\Users\pratik\Anaconda3\lib\site-packages\flask\_compat.py", line 35, in reraise
    raise value
  File "C:\Users\pratik\Anaconda3\lib\site-packages\flask\app.py", line 1813, in full_dispatch_request
    rv = self.dispatch_request()
  File "C:\Users\pratik\Anaconda3\lib\site-packages\flask\app.py", line 1799, in dispatch_request
    return self.view_functions[rule.endpoint](**req.view_args)
  File "api_speedo.py", line 95, in test_post
    return jsonify(resp)
  File "C:\Users\pratik\Anaconda3\lib\site-packages\flask\json\__init__.py", line 321, in jsonify
    dumps(data, indent=indent, separators=separators) + '\n',
  File "C:\Users\pratik\Anaconda3\lib\site-packages\flask\json\__init__.py", line 179, in dumps
    rv = _json.dumps(obj, **kwargs)
  File "C:\Users\pratik\Anaconda3\lib\site-packages\simplejson\__init__.py", line 399, in dumps
    **kw).encode(obj)
  File "C:\Users\pratik\Anaconda3\lib\site-packages\simplejson\encoder.py", line 296, in encode
    chunks = self.iterencode(o, _one_shot=True)
  File "C:\Users\pratik\Anaconda3\lib\site-packages\simplejson\encoder.py", line 378, in iterencode
    return _iterencode(o, 0)
  File "C:\Users\pratik\Anaconda3\lib\site-packages\flask\json\__init__.py", line 81, in default
    return _json.JSONEncoder.default(self, o)
  File "C:\Users\pratik\Anaconda3\lib\site-packages\simplejson\encoder.py", line 273, in default
    o.__class__.__name__)
TypeError: Object of type int16 is not JSON serializable
Exception on /testpost [POST]
Traceback (most recent call last):
  File "C:\Users\pratik\Anaconda3\lib\site-packages\flask\app.py", line 2292, in wsgi_app
    response = self.full_dispatch_request()
  File "C:\Users\pratik\Anaconda3\lib\site-packages\flask\app.py", line 1815, in full_dispatch_request
    rv = self.handle_user_exception(e)
  File "C:\Users\pratik\Anaconda3\lib\site-packages\flask_cors\extension.py", line 161, in wrapped_function
    return cors_after_request(app.make_response(f(*args, **kwargs)))
  File "C:\Users\pratik\Anaconda3\lib\site-packages\flask\app.py", line 1718, in handle_user_exception
    reraise(exc_type, exc_value, tb)
  File "C:\Users\pratik\Anaconda3\lib\site-packages\flask\_compat.py", line 35, in reraise
    raise value
  File "C:\Users\pratik\Anaconda3\lib\site-packages\flask\app.py", line 1813, in full_dispatch_request
    rv = self.dispatch_request()
  File "C:\Users\pratik\Anaconda3\lib\site-packages\flask\app.py", line 1799, in dispatch_request
    return self.view_functions[rule.endpoint](**req.view_args)
  File "api_speedo.py", line 95, in test_post
    return jsonify(resp)
  File "C:\Users\pratik\Anaconda3\lib\site-packages\flask\json\__init__.py", line 321, in jsonify
    dumps(data, indent=indent, separators=separators) + '\n',
  File "C:\Users\pratik\Anaconda3\lib\site-packages\flask\json\__init__.py", line 179, in dumps
    rv = _json.dumps(obj, **kwargs)
  File "C:\Users\pratik\Anaconda3\lib\site-packages\simplejson\__init__.py", line 399, in dumps
    **kw).encode(obj)
  File "C:\Users\pratik\Anaconda3\lib\site-packages\simplejson\encoder.py", line 296, in encode
    chunks = self.iterencode(o, _one_shot=True)
  File "C:\Users\pratik\Anaconda3\lib\site-packages\simplejson\encoder.py", line 378, in iterencode
    return _iterencode(o, 0)
  File "C:\Users\pratik\Anaconda3\lib\site-packages\flask\json\__init__.py", line 81, in default
    return _json.JSONEncoder.default(self, o)
  File "C:\Users\pratik\Anaconda3\lib\site-packages\simplejson\encoder.py", line 273, in default
    o.__class__.__name__)
TypeError: Object of type int16 is not JSON serializable
Exception on /testpost [POST]
Traceback (most recent call last):
  File "C:\Users\pratik\Anaconda3\lib\site-packages\flask\app.py", line 2292, in wsgi_app
    response = self.full_dispatch_request()
  File "C:\Users\pratik\Anaconda3\lib\site-packages\flask\app.py", line 1815, in full_dispatch_request
    rv = self.handle_user_exception(e)
  File "C:\Users\pratik\Anaconda3\lib\site-packages\flask_cors\extension.py", line 161, in wrapped_function
    return cors_after_request(app.make_response(f(*args, **kwargs)))
  File "C:\Users\pratik\Anaconda3\lib\site-packages\flask\app.py", line 1718, in handle_user_exception
    reraise(exc_type, exc_value, tb)
  File "C:\Users\pratik\Anaconda3\lib\site-packages\flask\_compat.py", line 35, in reraise
    raise value
  File "C:\Users\pratik\Anaconda3\lib\site-packages\flask\app.py", line 1813, in full_dispatch_request
    rv = self.dispatch_request()
  File "C:\Users\pratik\Anaconda3\lib\site-packages\flask\app.py", line 1799, in dispatch_request
    return self.view_functions[rule.endpoint](**req.view_args)
  File "api_speedo.py", line 66, in test_post
    resp = {"data1":img1 ,"data2":img2,"data3":img3 ,"data4":img4,"data6":img5,"data7":json.dumps(list1.tolist()) }
AttributeError: 'list' object has no attribute 'tolist'
Exception on /testpost [POST]
Traceback (most recent call last):
  File "C:\Users\pratik\Anaconda3\lib\site-packages\flask\app.py", line 2292, in wsgi_app
    response = self.full_dispatch_request()
  File "C:\Users\pratik\Anaconda3\lib\site-packages\flask\app.py", line 1815, in full_dispatch_request
    rv = self.handle_user_exception(e)
  File "C:\Users\pratik\Anaconda3\lib\site-packages\flask_cors\extension.py", line 161, in wrapped_function
    return cors_after_request(app.make_response(f(*args, **kwargs)))
  File "C:\Users\pratik\Anaconda3\lib\site-packages\flask\app.py", line 1718, in handle_user_exception
    reraise(exc_type, exc_value, tb)
  File "C:\Users\pratik\Anaconda3\lib\site-packages\flask\_compat.py", line 35, in reraise
    raise value
  File "C:\Users\pratik\Anaconda3\lib\site-packages\flask\app.py", line 1813, in full_dispatch_request
    rv = self.dispatch_request()
  File "C:\Users\pratik\Anaconda3\lib\site-packages\flask\app.py", line 1799, in dispatch_request
    return self.view_functions[rule.endpoint](**req.view_args)
  File "api_speedo.py", line 66, in test_post
    resp = {"data1":img1 ,"data2":img2,"data3":img3 ,"data4":img4,"data6":img5,"data7":json.dumps(list1) }
  File "C:\Users\pratik\Anaconda3\lib\json\__init__.py", line 231, in dumps
    return _default_encoder.encode(obj)
  File "C:\Users\pratik\Anaconda3\lib\json\encoder.py", line 199, in encode
    chunks = self.iterencode(o, _one_shot=True)
  File "C:\Users\pratik\Anaconda3\lib\json\encoder.py", line 257, in iterencode
    return _iterencode(o, 0)
  File "C:\Users\pratik\Anaconda3\lib\json\encoder.py", line 180, in default
    o.__class__.__name__)
TypeError: Object of type 'int16' is not JSON serializable
Exception on /testpost [POST]
Traceback (most recent call last):
  File "C:\Users\pratik\Anaconda3\lib\site-packages\flask\app.py", line 2292, in wsgi_app
    response = self.full_dispatch_request()
  File "C:\Users\pratik\Anaconda3\lib\site-packages\flask\app.py", line 1815, in full_dispatch_request
    rv = self.handle_user_exception(e)
  File "C:\Users\pratik\Anaconda3\lib\site-packages\flask_cors\extension.py", line 161, in wrapped_function
    return cors_after_request(app.make_response(f(*args, **kwargs)))
  File "C:\Users\pratik\Anaconda3\lib\site-packages\flask\app.py", line 1718, in handle_user_exception
    reraise(exc_type, exc_value, tb)
  File "C:\Users\pratik\Anaconda3\lib\site-packages\flask\_compat.py", line 35, in reraise
    raise value
  File "C:\Users\pratik\Anaconda3\lib\site-packages\flask\app.py", line 1813, in full_dispatch_request
    rv = self.dispatch_request()
  File "C:\Users\pratik\Anaconda3\lib\site-packages\flask\app.py", line 1799, in dispatch_request
    return self.view_functions[rule.endpoint](**req.view_args)
  File "api_speedo.py", line 66, in test_post
    resp = {"data1":img1 ,"data2":img2,"data3":img3 ,"data4":img4,"data6":img5,"data7":json.dumps(list1) }
  File "C:\Users\pratik\Anaconda3\lib\json\__init__.py", line 231, in dumps
    return _default_encoder.encode(obj)
  File "C:\Users\pratik\Anaconda3\lib\json\encoder.py", line 199, in encode
    chunks = self.iterencode(o, _one_shot=True)
  File "C:\Users\pratik\Anaconda3\lib\json\encoder.py", line 257, in iterencode
    return _iterencode(o, 0)
  File "C:\Users\pratik\Anaconda3\lib\json\encoder.py", line 180, in default
    o.__class__.__name__)
TypeError: Object of type 'int16' is not JSON serializable
Exception on /testpost [POST]
Traceback (most recent call last):
  File "C:\Users\pratik\Anaconda3\lib\site-packages\flask\app.py", line 2292, in wsgi_app
    response = self.full_dispatch_request()
  File "C:\Users\pratik\Anaconda3\lib\site-packages\flask\app.py", line 1815, in full_dispatch_request
    rv = self.handle_user_exception(e)
  File "C:\Users\pratik\Anaconda3\lib\site-packages\flask_cors\extension.py", line 161, in wrapped_function
    return cors_after_request(app.make_response(f(*args, **kwargs)))
  File "C:\Users\pratik\Anaconda3\lib\site-packages\flask\app.py", line 1718, in handle_user_exception
    reraise(exc_type, exc_value, tb)
  File "C:\Users\pratik\Anaconda3\lib\site-packages\flask\_compat.py", line 35, in reraise
    raise value
  File "C:\Users\pratik\Anaconda3\lib\site-packages\flask\app.py", line 1813, in full_dispatch_request
    rv = self.dispatch_request()
  File "C:\Users\pratik\Anaconda3\lib\site-packages\flask\app.py", line 1799, in dispatch_request
    return self.view_functions[rule.endpoint](**req.view_args)
  File "api_speedo.py", line 107, in test_post
    return jsonify(resp)
UnboundLocalError: local variable 'resp' referenced before assignment
Exception on /testpost [POST]
Traceback (most recent call last):
  File "C:\Users\pratik\Anaconda3\lib\site-packages\flask\app.py", line 2292, in wsgi_app
    response = self.full_dispatch_request()
  File "C:\Users\pratik\Anaconda3\lib\site-packages\flask\app.py", line 1815, in full_dispatch_request
    rv = self.handle_user_exception(e)
  File "C:\Users\pratik\Anaconda3\lib\site-packages\flask_cors\extension.py", line 161, in wrapped_function
    return cors_after_request(app.make_response(f(*args, **kwargs)))
  File "C:\Users\pratik\Anaconda3\lib\site-packages\flask\app.py", line 1718, in handle_user_exception
    reraise(exc_type, exc_value, tb)
  File "C:\Users\pratik\Anaconda3\lib\site-packages\flask\_compat.py", line 35, in reraise
    raise value
  File "C:\Users\pratik\Anaconda3\lib\site-packages\flask\app.py", line 1813, in full_dispatch_request
    rv = self.dispatch_request()
  File "C:\Users\pratik\Anaconda3\lib\site-packages\flask\app.py", line 1799, in dispatch_request
    return self.view_functions[rule.endpoint](**req.view_args)
  File "api_speedo.py", line 111, in test_post
    fs, Audiodata = wavfile.read(AudioName)
  File "C:\Users\pratik\Anaconda3\lib\site-packages\scipy\io\wavfile.py", line 233, in read
    fid = open(filename, 'rb')
FileNotFoundError: [Errno 2] No such file or directory: 'combined_changed_final.wav'
Exception on /testpost [POST]
Traceback (most recent call last):
  File "C:\Users\pratik\Anaconda3\lib\site-packages\flask\app.py", line 2292, in wsgi_app
    response = self.full_dispatch_request()
  File "C:\Users\pratik\Anaconda3\lib\site-packages\flask\app.py", line 1815, in full_dispatch_request
    rv = self.handle_user_exception(e)
  File "C:\Users\pratik\Anaconda3\lib\site-packages\flask_cors\extension.py", line 161, in wrapped_function
    return cors_after_request(app.make_response(f(*args, **kwargs)))
  File "C:\Users\pratik\Anaconda3\lib\site-packages\flask\app.py", line 1718, in handle_user_exception
    reraise(exc_type, exc_value, tb)
  File "C:\Users\pratik\Anaconda3\lib\site-packages\flask\_compat.py", line 35, in reraise
    raise value
  File "C:\Users\pratik\Anaconda3\lib\site-packages\flask\app.py", line 1813, in full_dispatch_request
    rv = self.dispatch_request()
  File "C:\Users\pratik\Anaconda3\lib\site-packages\flask\app.py", line 1799, in dispatch_request
    return self.view_functions[rule.endpoint](**req.view_args)
  File "api_speedo.py", line 116, in test_post
    resp = {"data1":img1 ,"data2":img2,"data3":img3 ,"data4":img4,"data6":img5,"data7":img6,"data8":ans }
UnboundLocalError: local variable 'img1' referenced before assignment
